Workbook

Sheet 00_HUONG_DAN
A1: HỆ THỐNG TẠO ĐỀ JFT-BASIC — PHẠM VI いろどり
A3: FLOW | B3: Kế hoạch → Nhập nguồn → Nhập yêu cầu theo dạng bài → AI sinh → Duyệt → Ráp đề → Xuất LMS → Thống kê
A5: Nhóm sheet | B5: Vai trò
A6: 01_KE_HOACH | B6: Lên kế hoạch từng đề thi thử: ngày thi, phạm vi bài, số câu mỗi dạng, người phụ trách
A7: 02_THONG_KE | B7: Tự động: số câu theo dạng × trạng thái, độ phủ theo bài, đủ/thiếu so với kế hoạch
A8: 10–13_NGUON_* | B8: Dữ liệu nguồn từ giáo trình Irodori: từ vựng, kanji, ngữ pháp, tình huống. AI chỉ được dùng trong phạm vi này
A9: IN_01 → IN_11 | B9: Phiếu yêu cầu sinh câu cho từng dạng bài. 1 dòng = 1 yêu cầu (có thể sinh nhiều câu)
A10: 20_PROMPT | B10: Mẫu prompt cho từng dạng bài, Apps Script thay {biến} bằng dữ liệu dòng IN_xx
A11: 30_NGAN_HANG | B11: Ngân hàng câu hỏi sau khi AI sinh + cột duyệt VN/JP
A12: 40_RAP_DE | B12: Danh sách câu đã chọn cho từng mã đề → xuất file import LMS
A13: 99_DANH_MUC | B13: Danh mục dùng cho dropdown. Sửa ở đây, không sửa trong ô
A15: Màu tiêu đề cột
A16: Xanh dương nhạt | B16: Trường chung — bắt buộc ở mọi dạng bài
A17: Cam nhạt | B17: Trường riêng của dạng bài
A18: Vàng | B18: Gợi ý cho AI (không bắt buộc, để trống thì AI tự chọn)
A19: Xanh lá | B19: Tự động — KHÔNG nhập tay (công thức / Apps Script ghi)
A21: Quy tắc nhập
A22: 1 | B22: Tiếng Nhật nhập đúng dạng sẽ xuất hiện trong đề (kanji + furigana theo chuẩn JFT nếu cần)
A23: 2 | B23: Nhiều giá trị trong 1 ô: ngăn cách bằng dấu ; (ví dụ: 朝ご飯;昼ご飯;晩ご飯)
A24: 3 | B24: Chỉ đổi Trạng thái = "Sẵn sàng sinh" khi đã điền đủ trường bắt buộc
A25: 4 | B25: Mỗi câu AI sinh luôn vào Draft — chỉ câu Approved mới được ráp đề
A26: 5 | B26: Dòng có chữ VÍ DỤ ở cột Ghi chú là dòng mẫu minh hoạ — xoá trước khi chạy thật

Sheet 01_KE_HOACH
A1: Mỗi dòng = 1 đề thi thử. Số câu mỗi dạng lấy theo cấu trúc đề JFT chính thức (đối chiếu đề mẫu Japan Foundation).
A2: Mã đề | B2: Tên đề | C2: Lớp / đối tượng | D2: Ngày thi | E2: Quyển | F2: Bài từ | G2: Bài đến | H2: 語の意味 | I2: 語の使い方 | J2: 漢字の読み | K2: 漢字の表記 | L2: 表現 | M2: 文法 | N2: 会話の聴解 | O2: アナウンス | P2: 指示の聴解 | Q2: 掲示の読解 | R2: 文章の読解 | S2: Tổng câu | T2: Phụ trách | U2: Deadline duyệt | V2: Trạng thái | W2: Ghi chú
A3: TT-2026-01 | B3: Thi thử giữa khoá (VÍ DỤ) | E3: 入門 | F3: 1 | G3: 9 | S3: =IF(A3="","",SUM(H3:R3))
S4: =IF(A4="","",SUM(H4:R4))
S5: =IF(A5="","",SUM(H5:R5))
S6: =IF(A6="","",SUM(H6:R6))
S7: =IF(A7="","",SUM(H7:R7))
S8: =IF(A8="","",SUM(H8:R8))
S9: =IF(A9="","",SUM(H9:R9))
S10: =IF(A10="","",SUM(H10:R10))
S11: =IF(A11="","",SUM(H11:R11))
S12: =IF(A12="","",SUM(H12:R12))
S13: =IF(A13="","",SUM(H13:R13))
S14: =IF(A14="","",SUM(H14:R14))
S15: =IF(A15="","",SUM(H15:R15))
... S200: =IF(A200="","",SUM(H200:R200))

Sheet 02_THONG_KE
A1: A. Ngân hàng câu hỏi theo dạng bài × trạng thái
A2: Phần thi | B2: Dạng bài | C2: Draft | D2: Đang duyệt VN | E2: Đang duyệt JP | F2: Cần sửa | G2: Approved | H2: Loại | I2: Tổng | J2: Yêu cầu chưa sinh
A3: 文字と語彙 | B3: 語の意味 | C3: =COUNTIFS('30_NGAN_HANG'!$D:$D,$B3,'30_NGAN_HANG'!$Y:$Y,"Draft") | D3: =COUNTIFS('30_NGAN_HANG'!$D:$D,$B3,'30_NGAN_HANG'!$Y:$Y,"Đang duyệt VN") | E3: =COUNTIFS('30_NGAN_HANG'!$D:$D,$B3,'30_NGAN_HANG'!$Y:$Y,"Đang duyệt JP") | F3: =COUNTIFS('30_NGAN_HANG'!$D:$D,$B3,'30_NGAN_HANG'!$Y:$Y,"Cần sửa") | G3: =COUNTIFS('30_NGAN_HANG'!$D:$D,$B3,'30_NGAN_HANG'!$Y:$Y,"Approved") | H3: =COUNTIFS('30_NGAN_HANG'!$D:$D,$B3,'30_NGAN_HANG'!$Y:$Y,"Loại") | I3: =COUNTIF('30_NGAN_HANG'!$D:$D,$B3) | J3: =COUNTIF('IN_01_語の意味'!$A:$Z,"Sẵn sàng sinh")
A4: 文字と語彙 | B4: 語の使い方 | C4: =COUNTIFS('30_NGAN_HANG'!$D:$D,$B4,'30_NGAN_HANG'!$Y:$Y,"Draft") | D4: =COUNTIFS('30_NGAN_HANG'!$D:$D,$B4,'30_NGAN_HANG'!$Y:$Y,"Đang duyệt VN") | E4: =COUNTIFS('30_NGAN_HANG'!$D:$D,$B4,'30_NGAN_HANG'!$Y:$Y,"Đang duyệt JP") | F4: =COUNTIFS('30_NGAN_HANG'!$D:$D,$B4,'30_NGAN_HANG'!$Y:$Y,"Cần sửa") | G4: =COUNTIFS('30_NGAN_HANG'!$D:$D,$B4,'30_NGAN_HANG'!$Y:$Y,"Approved") | H4: =COUNTIFS('30_NGAN_HANG'!$D:$D,$B4,'30_NGAN_HANG'!$Y:$Y,"Loại") | I4: =COUNTIF('30_NGAN_HANG'!$D:$D,$B4) | J4: =COUNTIF('IN_02_語の使い方'!$A:$Z,"Sẵn sàng sinh")
A5: 文字と語彙 | B5: 漢字の読み | C5: =COUNTIFS('30_NGAN_HANG'!$D:$D,$B5,'30_NGAN_HANG'!$Y:$Y,"Draft") | D5: =COUNTIFS('30_NGAN_HANG'!$D:$D,$B5,'30_NGAN_HANG'!$Y:$Y,"Đang duyệt VN") | E5: =COUNTIFS('30_NGAN_HANG'!$D:$D,$B5,'30_NGAN_HANG'!$Y:$Y,"Đang duyệt JP") | F5: =COUNTIFS('30_NGAN_HANG'!$D:$D,$B5,'30_NGAN_HANG'!$Y:$Y,"Cần sửa") | G5: =COUNTIFS('30_NGAN_HANG'!$D:$D,$B5,'30_NGAN_HANG'!$Y:$Y,"Approved") | H5: =COUNTIFS('30_NGAN_HANG'!$D:$D,$B5,'30_NGAN_HANG'!$Y:$Y,"Loại") | I5: =COUNTIF('30_NGAN_HANG'!$D:$D,$B5) | J5: =COUNTIF('IN_03_漢字の読み'!$A:$Z,"Sẵn sàng sinh")
A6: 文字と語彙 | B6: 漢字の表記 | C6: =COUNTIFS('30_NGAN_HANG'!$D:$D,$B6,'30_NGAN_HANG'!$Y:$Y,"Draft") | D6: =COUNTIFS('30_NGAN_HANG'!$D:$D,$B6,'30_NGAN_HANG'!$Y:$Y,"Đang duyệt VN") | E6: =COUNTIFS('30_NGAN_HANG'!$D:$D,$B6,'30_NGAN_HANG'!$Y:$Y,"Đang duyệt JP") | F6: =COUNTIFS('30_NGAN_HANG'!$D:$D,$B6,'30_NGAN_HANG'!$Y:$Y,"Cần sửa") | G6: =COUNTIFS('30_NGAN_HANG'!$D:$D,$B6,'30_NGAN_HANG'!$Y:$Y,"Approved") | H6: =COUNTIFS('30_NGAN_HANG'!$D:$D,$B6,'30_NGAN_HANG'!$Y:$Y,"Loại") | I6: =COUNTIF('30_NGAN_HANG'!$D:$D,$B6) | J6: =COUNTIF('IN_04_漢字の表記'!$A:$Z,"Sẵn sàng sinh")
A7: 会話と表現 | B7: 表現 | C7: =COUNTIFS('30_NGAN_HANG'!$D:$D,$B7,'30_NGAN_HANG'!$Y:$Y,"Draft") | D7: =COUNTIFS('30_NGAN_HANG'!$D:$D,$B7,'30_NGAN_HANG'!$Y:$Y,"Đang duyệt VN") | E7: =COUNTIFS('30_NGAN_HANG'!$D:$D,$B7,'30_NGAN_HANG'!$Y:$Y,"Đang duyệt JP") | F7: =COUNTIFS('30_NGAN_HANG'!$D:$D,$B7,'30_NGAN_HANG'!$Y:$Y,"Cần sửa") | G7: =COUNTIFS('30_NGAN_HANG'!$D:$D,$B7,'30_NGAN_HANG'!$Y:$Y,"Approved") | H7: =COUNTIFS('30_NGAN_HANG'!$D:$D,$B7,'30_NGAN_HANG'!$Y:$Y,"Loại") | I7: =COUNTIF('30_NGAN_HANG'!$D:$D,$B7) | J7: =COUNTIF('IN_05_表現'!$A:$Z,"Sẵn sàng sinh")
A8: 会話と表現 | B8: 文法 | C8: =COUNTIFS('30_NGAN_HANG'!$D:$D,$B8,'30_NGAN_HANG'!$Y:$Y,"Draft") | D8: =COUNTIFS('30_NGAN_HANG'!$D:$D,$B8,'30_NGAN_HANG'!$Y:$Y,"Đang duyệt VN") | E8: =COUNTIFS('30_NGAN_HANG'!$D:$D,$B8,'30_NGAN_HANG'!$Y:$Y,"Đang duyệt JP") | F8: =COUNTIFS('30_NGAN_HANG'!$D:$D,$B8,'30_NGAN_HANG'!$Y:$Y,"Cần sửa") | G8: =COUNTIFS('30_NGAN_HANG'!$D:$D,$B8,'30_NGAN_HANG'!$Y:$Y,"Approved") | H8: =COUNTIFS('30_NGAN_HANG'!$D:$D,$B8,'30_NGAN_HANG'!$Y:$Y,"Loại") | I8: =COUNTIF('30_NGAN_HANG'!$D:$D,$B8) | J8: =COUNTIF('IN_06_文法'!$A:$Z,"Sẵn sàng sinh")
A9: 聴解 | B9: 会話の聴解 | C9: =COUNTIFS('30_NGAN_HANG'!$D:$D,$B9,'30_NGAN_HANG'!$Y:$Y,"Draft") | D9: =COUNTIFS('30_NGAN_HANG'!$D:$D,$B9,'30_NGAN_HANG'!$Y:$Y,"Đang duyệt VN") | E9: =COUNTIFS('30_NGAN_HANG'!$D:$D,$B9,'30_NGAN_HANG'!$Y:$Y,"Đang duyệt JP") | F9: =COUNTIFS('30_NGAN_HANG'!$D:$D,$B9,'30_NGAN_HANG'!$Y:$Y,"Cần sửa") | G9: =COUNTIFS('30_NGAN_HANG'!$D:$D,$B9,'30_NGAN_HANG'!$Y:$Y,"Approved") | H9: =COUNTIFS('30_NGAN_HANG'!$D:$D,$B9,'30_NGAN_HANG'!$Y:$Y,"Loại") | I9: =COUNTIF('30_NGAN_HANG'!$D:$D,$B9) | J9: =COUNTIF('IN_07_会話の聴解'!$A:$Z,"Sẵn sàng sinh")
A10: 聴解 | B10: アナウンス | C10: =COUNTIFS('30_NGAN_HANG'!$D:$D,$B10,'30_NGAN_HANG'!$Y:$Y,"Draft") | D10: =COUNTIFS('30_NGAN_HANG'!$D:$D,$B10,'30_NGAN_HANG'!$Y:$Y,"Đang duyệt VN") | E10: =COUNTIFS('30_NGAN_HANG'!$D:$D,$B10,'30_NGAN_HANG'!$Y:$Y,"Đang duyệt JP") | F10: =COUNTIFS('30_NGAN_HANG'!$D:$D,$B10,'30_NGAN_HANG'!$Y:$Y,"Cần sửa") | G10: =COUNTIFS('30_NGAN_HANG'!$D:$D,$B10,'30_NGAN_HANG'!$Y:$Y,"Approved") | H10: =COUNTIFS('30_NGAN_HANG'!$D:$D,$B10,'30_NGAN_HANG'!$Y:$Y,"Loại") | I10: =COUNTIF('30_NGAN_HANG'!$D:$D,$B10) | J10: =COUNTIF('IN_08_アナウンス'!$A:$Z,"Sẵn sàng sinh")
A11: 聴解 | B11: 指示の聴解 | C11: =COUNTIFS('30_NGAN_HANG'!$D:$D,$B11,'30_NGAN_HANG'!$Y:$Y,"Draft") | D11: =COUNTIFS('30_NGAN_HANG'!$D:$D,$B11,'30_NGAN_HANG'!$Y:$Y,"Đang duyệt VN") | E11: =COUNTIFS('30_NGAN_HANG'!$D:$D,$B11,'30_NGAN_HANG'!$Y:$Y,"Đang duyệt JP") | F11: =COUNTIFS('30_NGAN_HANG'!$D:$D,$B11,'30_NGAN_HANG'!$Y:$Y,"Cần sửa") | G11: =COUNTIFS('30_NGAN_HANG'!$D:$D,$B11,'30_NGAN_HANG'!$Y:$Y,"Approved") | H11: =COUNTIFS('30_NGAN_HANG'!$D:$D,$B11,'30_NGAN_HANG'!$Y:$Y,"Loại") | I11: =COUNTIF('30_NGAN_HANG'!$D:$D,$B11) | J11: =COUNTIF('IN_09_指示の聴解'!$A:$Z,"Sẵn sàng sinh")
A12: 読解 | B12: 掲示の読解 | C12: =COUNTIFS('30_NGAN_HANG'!$D:$D,$B12,'30_NGAN_HANG'!$Y:$Y,"Draft") | D12: =COUNTIFS('30_NGAN_HANG'!$D:$D,$B12,'30_NGAN_HANG'!$Y:$Y,"Đang duyệt VN") | E12: =COUNTIFS('30_NGAN_HANG'!$D:$D,$B12,'30_NGAN_HANG'!$Y:$Y,"Đang duyệt JP") | F12: =COUNTIFS('30_NGAN_HANG'!$D:$D,$B12,'30_NGAN_HANG'!$Y:$Y,"Cần sửa") | G12: =COUNTIFS('30_NGAN_HANG'!$D:$D,$B12,'30_NGAN_HANG'!$Y:$Y,"Approved") | H12: =COUNTIFS('30_NGAN_HANG'!$D:$D,$B12,'30_NGAN_HANG'!$Y:$Y,"Loại") | I12: =COUNTIF('30_NGAN_HANG'!$D:$D,$B12) | J12: =COUNTIF('IN_10_掲示の読解'!$A:$Z,"Sẵn sàng sinh")
A13: 読解 | B13: 文章の読解 | C13: =COUNTIFS('30_NGAN_HANG'!$D:$D,$B13,'30_NGAN_HANG'!$Y:$Y,"Draft") | D13: =COUNTIFS('30_NGAN_HANG'!$D:$D,$B13,'30_NGAN_HANG'!$Y:$Y,"Đang duyệt VN") | E13: =COUNTIFS('30_NGAN_HANG'!$D:$D,$B13,'30_NGAN_HANG'!$Y:$Y,"Đang duyệt JP") | F13: =COUNTIFS('30_NGAN_HANG'!$D:$D,$B13,'30_NGAN_HANG'!$Y:$Y,"Cần sửa") | G13: =COUNTIFS('30_NGAN_HANG'!$D:$D,$B13,'30_NGAN_HANG'!$Y:$Y,"Approved") | H13: =COUNTIFS('30_NGAN_HANG'!$D:$D,$B13,'30_NGAN_HANG'!$Y:$Y,"Loại") | I13: =COUNTIF('30_NGAN_HANG'!$D:$D,$B13) | J13: =COUNTIF('IN_11_文章の読解'!$A:$Z,"Sẵn sàng sinh")
A16: B. Đủ / thiếu câu Approved cho 1 mã đề
A17: Nhập mã đề → | B17: TT-2026-01
A18: Dạng bài | B18: Cần (kế hoạch) | C18: Approved hiện có | D18: Thiếu
A19: 語の意味 | B19: =IFERROR(INDEX('01_KE_HOACH'!H:H,MATCH($B$17,'01_KE_HOACH'!$A:$A,0)),0) | C19: =COUNTIFS('30_NGAN_HANG'!$D:$D,A19,'30_NGAN_HANG'!$Y:$Y,"Approved") | D19: =MAX(0,B19-C19)
A20: 語の使い方 | B20: =IFERROR(INDEX('01_KE_HOACH'!I:I,MATCH($B$17,'01_KE_HOACH'!$A:$A,0)),0) | C20: =COUNTIFS('30_NGAN_HANG'!$D:$D,A20,'30_NGAN_HANG'!$Y:$Y,"Approved") | D20: =MAX(0,B20-C20)
A21: 漢字の読み | B21: =IFERROR(INDEX('01_KE_HOACH'!J:J,MATCH($B$17,'01_KE_HOACH'!$A:$A,0)),0) | C21: =COUNTIFS('30_NGAN_HANG'!$D:$D,A21,'30_NGAN_HANG'!$Y:$Y,"Approved") | D21: =MAX(0,B21-C21)
A22: 漢字の表記 | B22: =IFERROR(INDEX('01_KE_HOACH'!K:K,MATCH($B$17,'01_KE_HOACH'!$A:$A,0)),0) | C22: =COUNTIFS('30_NGAN_HANG'!$D:$D,A22,'30_NGAN_HANG'!$Y:$Y,"Approved") | D22: =MAX(0,B22-C22)
A23: 表現 | B23: =IFERROR(INDEX('01_KE_HOACH'!L:L,MATCH($B$17,'01_KE_HOACH'!$A:$A,0)),0) | C23: =COUNTIFS('30_NGAN_HANG'!$D:$D,A23,'30_NGAN_HANG'!$Y:$Y,"Approved") | D23: =MAX(0,B23-C23)
A24: 文法 | B24: =IFERROR(INDEX('01_KE_HOACH'!M:M,MATCH($B$17,'01_KE_HOACH'!$A:$A,0)),0) | C24: =COUNTIFS('30_NGAN_HANG'!$D:$D,A24,'30_NGAN_HANG'!$Y:$Y,"Approved") | D24: =MAX(0,B24-C24)
A25: 会話の聴解 | B25: =IFERROR(INDEX('01_KE_HOACH'!N:N,MATCH($B$17,'01_KE_HOACH'!$A:$A,0)),0) | C25: =COUNTIFS('30_NGAN_HANG'!$D:$D,A25,'30_NGAN_HANG'!$Y:$Y,"Approved") | D25: =MAX(0,B25-C25)
A26: アナウンス | B26: =IFERROR(INDEX('01_KE_HOACH'!O:O,MATCH($B$17,'01_KE_HOACH'!$A:$A,0)),0) | C26: =COUNTIFS('30_NGAN_HANG'!$D:$D,A26,'30_NGAN_HANG'!$Y:$Y,"Approved") | D26: =MAX(0,B26-C26)
A27: 指示の聴解 | B27: =IFERROR(INDEX('01_KE_HOACH'!P:P,MATCH($B$17,'01_KE_HOACH'!$A:$A,0)),0) | C27: =COUNTIFS('30_NGAN_HANG'!$D:$D,A27,'30_NGAN_HANG'!$Y:$Y,"Approved") | D27: =MAX(0,B27-C27)
A28: 掲示の読解 | B28: =IFERROR(INDEX('01_KE_HOACH'!Q:Q,MATCH($B$17,'01_KE_HOACH'!$A:$A,0)),0) | C28: =COUNTIFS('30_NGAN_HANG'!$D:$D,A28,'30_NGAN_HANG'!$Y:$Y,"Approved") | D28: =MAX(0,B28-C28)
A29: 文章の読解 | B29: =IFERROR(INDEX('01_KE_HOACH'!R:R,MATCH($B$17,'01_KE_HOACH'!$A:$A,0)),0) | C29: =COUNTIFS('30_NGAN_HANG'!$D:$D,A29,'30_NGAN_HANG'!$Y:$Y,"Approved") | D29: =MAX(0,B29-C29)
A32: C. Độ phủ theo bài (số câu Approved)
A33: Quyển | B33: Bài | C33: 語の意味 | D33: 語の使い方 | E33: 漢字の読み | F33: 漢字の表記 | G33: 表現 | H33: 文法 | I33: 会話の聴解 | J33: アナウンス | K33: 指示の聴解 | L33: 掲示の読解 | M33: 文章の読解 | N33: Tổng
A34: 入門 | B34: 1 | C34: =COUNTIFS('30_NGAN_HANG'!$E:$E,$A34,'30_NGAN_HANG'!$F:$F,$B34,'30_NGAN_HANG'!$D:$D,"語の意味",'30_NGAN_HANG'!$Y:$Y,"Approved") | D34: =COUNTIFS('30_NGAN_HANG'!$E:$E,$A34,'30_NGAN_HANG'!$F:$F,$B34,'30_NGAN_HANG'!$D:$D,"語の使い方",'30_NGAN_HANG'!$Y:$Y,"Approved") | E34: =COUNTIFS('30_NGAN_HANG'!$E:$E,$A34,'30_NGAN_HANG'!$F:$F,$B34,'30_NGAN_HANG'!$D:$D,"漢字の読み",'30_NGAN_HANG'!$Y:$Y,"Approved") | F34: =COUNTIFS('30_NGAN_HANG'!$E:$E,$A34,'30_NGAN_HANG'!$F:$F,$B34,'30_NGAN_HANG'!$D:$D,"漢字の表記",'30_NGAN_HANG'!$Y:$Y,"Approved") | G34: =COUNTIFS('30_NGAN_HANG'!$E:$E,$A34,'30_NGAN_HANG'!$F:$F,$B34,'30_NGAN_HANG'!$D:$D,"表現",'30_NGAN_HANG'!$Y:$Y,"Approved") | H34: =COUNTIFS('30_NGAN_HANG'!$E:$E,$A34,'30_NGAN_HANG'!$F:$F,$B34,'30_NGAN_HANG'!$D:$D,"文法",'30_NGAN_HANG'!$Y:$Y,"Approved") | I34: =COUNTIFS('30_NGAN_HANG'!$E:$E,$A34,'30_NGAN_HANG'!$F:$F,$B34,'30_NGAN_HANG'!$D:$D,"会話の聴解",'30_NGAN_HANG'!$Y:$Y,"Approved") | J34: =COUNTIFS('30_NGAN_HANG'!$E:$E,$A34,'30_NGAN_HANG'!$F:$F,$B34,'30_NGAN_HANG'!$D:$D,"アナウンス",'30_NGAN_HANG'!$Y:$Y,"Approved") | K34: =COUNTIFS('30_NGAN_HANG'!$E:$E,$A34,'30_NGAN_HANG'!$F:$F,$B34,'30_NGAN_HANG'!$D:$D,"指示の聴解",'30_NGAN_HANG'!$Y:$Y,"Approved") | L34: =COUNTIFS('30_NGAN_HANG'!$E:$E,$A34,'30_NGAN_HANG'!$F:$F,$B34,'30_NGAN_HANG'!$D:$D,"掲示の読解",'30_NGAN_HANG'!$Y:$Y,"Approved") | M34: =COUNTIFS('30_NGAN_HANG'!$E:$E,$A34,'30_NGAN_HANG'!$F:$F,$B34,'30_NGAN_HANG'!$D:$D,"文章の読解",'30_NGAN_HANG'!$Y:$Y,"Approved") | N34: =SUM(C34:M34)
A35: 入門 | B35: 2 | C35: =COUNTIFS('30_NGAN_HANG'!$E:$E,$A35,'30_NGAN_HANG'!$F:$F,$B35,'30_NGAN_HANG'!$D:$D,"語の意味",'30_NGAN_HANG'!$Y:$Y,"Approved") | D35: =COUNTIFS('30_NGAN_HANG'!$E:$E,$A35,'30_NGAN_HANG'!$F:$F,$B35,'30_NGAN_HANG'!$D:$D,"語の使い方",'30_NGAN_HANG'!$Y:$Y,"Approved") | E35: =COUNTIFS('30_NGAN_HANG'!$E:$E,$A35,'30_NGAN_HANG'!$F:$F,$B35,'30_NGAN_HANG'!$D:$D,"漢字の読み",'30_NGAN_HANG'!$Y:$Y,"Approved") | F35: =COUNTIFS('30_NGAN_HANG'!$E:$E,$A35,'30_NGAN_HANG'!$F:$F,$B35,'30_NGAN_HANG'!$D:$D,"漢字の表記",'30_NGAN_HANG'!$Y:$Y,"Approved") | G35: =COUNTIFS('30_NGAN_HANG'!$E:$E,$A35,'30_NGAN_HANG'!$F:$F,$B35,'30_NGAN_HANG'!$D:$D,"表現",'30_NGAN_HANG'!$Y:$Y,"Approved") | H35: =COUNTIFS('30_NGAN_HANG'!$E:$E,$A35,'30_NGAN_HANG'!$F:$F,$B35,'30_NGAN_HANG'!$D:$D,"文法",'30_NGAN_HANG'!$Y:$Y,"Approved") | I35: =COUNTIFS('30_NGAN_HANG'!$E:$E,$A35,'30_NGAN_HANG'!$F:$F,$B35,'30_NGAN_HANG'!$D:$D,"会話の聴解",'30_NGAN_HANG'!$Y:$Y,"Approved") | J35: =COUNTIFS('30_NGAN_HANG'!$E:$E,$A35,'30_NGAN_HANG'!$F:$F,$B35,'30_NGAN_HANG'!$D:$D,"アナウンス",'30_NGAN_HANG'!$Y:$Y,"Approved") | K35: =COUNTIFS('30_NGAN_HANG'!$E:$E,$A35,'30_NGAN_HANG'!$F:$F,$B35,'30_NGAN_HANG'!$D:$D,"指示の聴解",'30_NGAN_HANG'!$Y:$Y,"Approved") | L35: =COUNTIFS('30_NGAN_HANG'!$E:$E,$A35,'30_NGAN_HANG'!$F:$F,$B35,'30_NGAN_HANG'!$D:$D,"掲示の読解",'30_NGAN_HANG'!$Y:$Y,"Approved") | M35: =COUNTIFS('30_NGAN_HANG'!$E:$E,$A35,'30_NGAN_HANG'!$F:$F,$B35,'30_NGAN_HANG'!$D:$D,"文章の読解",'30_NGAN_HANG'!$Y:$Y,"Approved") | N35: =SUM(C35:M35)
A36: 入門 | B36: 3 | C36: =COUNTIFS('30_NGAN_HANG'!$E:$E,$A36,'30_NGAN_HANG'!$F:$F,$B36,'30_NGAN_HANG'!$D:$D,"語の意味",'30_NGAN_HANG'!$Y:$Y,"Approved") | D36: =COUNTIFS('30_NGAN_HANG'!$E:$E,$A36,'30_NGAN_HANG'!$F:$F,$B36,'30_NGAN_HANG'!$D:$D,"語の使い方",'30_NGAN_HANG'!$Y:$Y,"Approved") | E36: =COUNTIFS('30_NGAN_HANG'!$E:$E,$A36,'30_NGAN_HANG'!$F:$F,$B36,'30_NGAN_HANG'!$D:$D,"漢字の読み",'30_NGAN_HANG'!$Y:$Y,"Approved") | F36: =COUNTIFS('30_NGAN_HANG'!$E:$E,$A36,'30_NGAN_HANG'!$F:$F,$B36,'30_NGAN_HANG'!$D:$D,"漢字の表記",'30_NGAN_HANG'!$Y:$Y,"Approved") | G36: =COUNTIFS('30_NGAN_HANG'!$E:$E,$A36,'30_NGAN_HANG'!$F:$F,$B36,'30_NGAN_HANG'!$D:$D,"表現",'30_NGAN_HANG'!$Y:$Y,"Approved") | H36: =COUNTIFS('30_NGAN_HANG'!$E:$E,$A36,'30_NGAN_HANG'!$F:$F,$B36,'30_NGAN_HANG'!$D:$D,"文法",'30_NGAN_HANG'!$Y:$Y,"Approved") | I36: =COUNTIFS('30_NGAN_HANG'!$E:$E,$A36,'30_NGAN_HANG'!$F:$F,$B36,'30_NGAN_HANG'!$D:$D,"会話の聴解",'30_NGAN_HANG'!$Y:$Y,"Approved") | J36: =COUNTIFS('30_NGAN_HANG'!$E:$E,$A36,'30_NGAN_HANG'!$F:$F,$B36,'30_NGAN_HANG'!$D:$D,"アナウンス",'30_NGAN_HANG'!$Y:$Y,"Approved") | K36: =COUNTIFS('30_NGAN_HANG'!$E:$E,$A36,'30_NGAN_HANG'!$F:$F,$B36,'30_NGAN_HANG'!$D:$D,"指示の聴解",'30_NGAN_HANG'!$Y:$Y,"Approved") | L36: =COUNTIFS('30_NGAN_HANG'!$E:$E,$A36,'30_NGAN_HANG'!$F:$F,$B36,'30_NGAN_HANG'!$D:$D,"掲示の読解",'30_NGAN_HANG'!$Y:$Y,"Approved") | M36: =COUNTIFS('30_NGAN_HANG'!$E:$E,$A36,'30_NGAN_HANG'!$F:$F,$B36,'30_NGAN_HANG'!$D:$D,"文章の読解",'30_NGAN_HANG'!$Y:$Y,"Approved") | N36: =SUM(C36:M36)
A37: 入門 | B37: 4 | C37: =COUNTIFS('30_NGAN_HANG'!$E:$E,$A37,'30_NGAN_HANG'!$F:$F,$B37,'30_NGAN_HANG'!$D:$D,"語の意味",'30_NGAN_HANG'!$Y:$Y,"Approved") | D37: =COUNTIFS('30_NGAN_HANG'!$E:$E,$A37,'30_NGAN_HANG'!$F:$F,$B37,'30_NGAN_HANG'!$D:$D,"語の使い方",'30_NGAN_HANG'!$Y:$Y,"Approved") | E37: =COUNTIFS('30_NGAN_HANG'!$E:$E,$A37,'30_NGAN_HANG'!$F:$F,$B37,'30_NGAN_HANG'!$D:$D,"漢字の読み",'30_NGAN_HANG'!$Y:$Y,"Approved") | F37: =COUNTIFS('30_NGAN_HANG'!$E:$E,$A37,'30_NGAN_HANG'!$F:$F,$B37,'30_NGAN_HANG'!$D:$D,"漢字の表記",'30_NGAN_HANG'!$Y:$Y,"Approved") | G37: =COUNTIFS('30_NGAN_HANG'!$E:$E,$A37,'30_NGAN_HANG'!$F:$F,$B37,'30_NGAN_HANG'!$D:$D,"表現",'30_NGAN_HANG'!$Y:$Y,"Approved") | H37: =COUNTIFS('30_NGAN_HANG'!$E:$E,$A37,'30_NGAN_HANG'!$F:$F,$B37,'30_NGAN_HANG'!$D:$D,"文法",'30_NGAN_HANG'!$Y:$Y,"Approved") | I37: =COUNTIFS('30_NGAN_HANG'!$E:$E,$A37,'30_NGAN_HANG'!$F:$F,$B37,'30_NGAN_HANG'!$D:$D,"会話の聴解",'30_NGAN_HANG'!$Y:$Y,"Approved") | J37: =COUNTIFS('30_NGAN_HANG'!$E:$E,$A37,'30_NGAN_HANG'!$F:$F,$B37,'30_NGAN_HANG'!$D:$D,"アナウンス",'30_NGAN_HANG'!$Y:$Y,"Approved") | K37: =COUNTIFS('30_NGAN_HANG'!$E:$E,$A37,'30_NGAN_HANG'!$F:$F,$B37,'30_NGAN_HANG'!$D:$D,"指示の聴解",'30_NGAN_HANG'!$Y:$Y,"Approved") | L37: =COUNTIFS('30_NGAN_HANG'!$E:$E,$A37,'30_NGAN_HANG'!$F:$F,$B37,'30_NGAN_HANG'!$D:$D,"掲示の読解",'30_NGAN_HANG'!$Y:$Y,"Approved") | M37: =COUNTIFS('30_NGAN_HANG'!$E:$E,$A37,'30_NGAN_HANG'!$F:$F,$B37,'30_NGAN_HANG'!$D:$D,"文章の読解",'30_NGAN_HANG'!$Y:$Y,"Approved") | N37: =SUM(C37:M37)
A38: 入門 | B38: 5 | C38: =COUNTIFS('30_NGAN_HANG'!$E:$E,$A38,'30_NGAN_HANG'!$F:$F,$B38,'30_NGAN_HANG'!$D:$D,"語の意味",'30_NGAN_HANG'!$Y:$Y,"Approved") | D38: =COUNTIFS('30_NGAN_HANG'!$E:$E,$A38,'30_NGAN_HANG'!$F:$F,$B38,'30_NGAN_HANG'!$D:$D,"語の使い方",'30_NGAN_HANG'!$Y:$Y,"Approved") | E38: =COUNTIFS('30_NGAN_HANG'!$E:$E,$A38,'30_NGAN_HANG'!$F:$F,$B38,'30_NGAN_HANG'!$D:$D,"漢字の読み",'30_NGAN_HANG'!$Y:$Y,"Approved") | F38: =COUNTIFS('30_NGAN_HANG'!$E:$E,$A38,'30_NGAN_HANG'!$F:$F,$B38,'30_NGAN_HANG'!$D:$D,"漢字の表記",'30_NGAN_HANG'!$Y:$Y,"Approved") | G38: =COUNTIFS('30_NGAN_HANG'!$E:$E,$A38,'30_NGAN_HANG'!$F:$F,$B38,'30_NGAN_HANG'!$D:$D,"表現",'30_NGAN_HANG'!$Y:$Y,"Approved") | H38: =COUNTIFS('30_NGAN_HANG'!$E:$E,$A38,'30_NGAN_HANG'!$F:$F,$B38,'30_NGAN_HANG'!$D:$D,"文法",'30_NGAN_HANG'!$Y:$Y,"Approved") | I38: =COUNTIFS('30_NGAN_HANG'!$E:$E,$A38,'30_NGAN_HANG'!$F:$F,$B38,'30_NGAN_HANG'!$D:$D,"会話の聴解",'30_NGAN_HANG'!$Y:$Y,"Approved") | J38: =COUNTIFS('30_NGAN_HANG'!$E:$E,$A38,'30_NGAN_HANG'!$F:$F,$B38,'30_NGAN_HANG'!$D:$D,"アナウンス",'30_NGAN_HANG'!$Y:$Y,"Approved") | K38: =COUNTIFS('30_NGAN_HANG'!$E:$E,$A38,'30_NGAN_HANG'!$F:$F,$B38,'30_NGAN_HANG'!$D:$D,"指示の聴解",'30_NGAN_HANG'!$Y:$Y,"Approved") | L38: =COUNTIFS('30_NGAN_HANG'!$E:$E,$A38,'30_NGAN_HANG'!$F:$F,$B38,'30_NGAN_HANG'!$D:$D,"掲示の読解",'30_NGAN_HANG'!$Y:$Y,"Approved") | M38: =COUNTIFS('30_NGAN_HANG'!$E:$E,$A38,'30_NGAN_HANG'!$F:$F,$B38,'30_NGAN_HANG'!$D:$D,"文章の読解",'30_NGAN_HANG'!$Y:$Y,"Approved") | N38: =SUM(C38:M38)
A39: 入門 | B39: 6 | C39: =COUNTIFS('30_NGAN_HANG'!$E:$E,$A39,'30_NGAN_HANG'!$F:$F,$B39,'30_NGAN_HANG'!$D:$D,"語の意味",'30_NGAN_HANG'!$Y:$Y,"Approved") | D39: =COUNTIFS('30_NGAN_HANG'!$E:$E,$A39,'30_NGAN_HANG'!$F:$F,$B39,'30_NGAN_HANG'!$D:$D,"語の使い方",'30_NGAN_HANG'!$Y:$Y,"Approved") | E39: =COUNTIFS('30_NGAN_HANG'!$E:$E,$A39,'30_NGAN_HANG'!$F:$F,$B39,'30_NGAN_HANG'!$D:$D,"漢字の読み",'30_NGAN_HANG'!$Y:$Y,"Approved") | F39: =COUNTIFS('30_NGAN_HANG'!$E:$E,$A39,'30_NGAN_HANG'!$F:$F,$B39,'30_NGAN_HANG'!$D:$D,"漢字の表記",'30_NGAN_HANG'!$Y:$Y,"Approved") | G39: =COUNTIFS('30_NGAN_HANG'!$E:$E,$A39,'30_NGAN_HANG'!$F:$F,$B39,'30_NGAN_HANG'!$D:$D,"表現",'30_NGAN_HANG'!$Y:$Y,"Approved") | H39: =COUNTIFS('30_NGAN_HANG'!$E:$E,$A39,'30_NGAN_HANG'!$F:$F,$B39,'30_NGAN_HANG'!$D:$D,"文法",'30_NGAN_HANG'!$Y:$Y,"Approved") | I39: =COUNTIFS('30_NGAN_HANG'!$E:$E,$A39,'30_NGAN_HANG'!$F:$F,$B39,'30_NGAN_HANG'!$D:$D,"会話の聴解",'30_NGAN_HANG'!$Y:$Y,"Approved") | J39: =COUNTIFS('30_NGAN_HANG'!$E:$E,$A39,'30_NGAN_HANG'!$F:$F,$B39,'30_NGAN_HANG'!$D:$D,"アナウンス",'30_NGAN_HANG'!$Y:$Y,"Approved") | K39: =COUNTIFS('30_NGAN_HANG'!$E:$E,$A39,'30_NGAN_HANG'!$F:$F,$B39,'30_NGAN_HANG'!$D:$D,"指示の聴解",'30_NGAN_HANG'!$Y:$Y,"Approved") | L39: =COUNTIFS('30_NGAN_HANG'!$E:$E,$A39,'30_NGAN_HANG'!$F:$F,$B39,'30_NGAN_HANG'!$D:$D,"掲示の読解",'30_NGAN_HANG'!$Y:$Y,"Approved") | M39: =COUNTIFS('30_NGAN_HANG'!$E:$E,$A39,'30_NGAN_HANG'!$F:$F,$B39,'30_NGAN_HANG'!$D:$D,"文章の読解",'30_NGAN_HANG'!$Y:$Y,"Approved") | N39: =SUM(C39:M39)
A40: 入門 | B40: 7 | C40: =COUNTIFS('30_NGAN_HANG'!$E:$E,$A40,'30_NGAN_HANG'!$F:$F,$B40,'30_NGAN_HANG'!$D:$D,"語の意味",'30_NGAN_HANG'!$Y:$Y,"Approved") | D40: =COUNTIFS('30_NGAN_HANG'!$E:$E,$A40,'30_NGAN_HANG'!$F:$F,$B40,'30_NGAN_HANG'!$D:$D,"語の使い方",'30_NGAN_HANG'!$Y:$Y,"Approved") | E40: =COUNTIFS('30_NGAN_HANG'!$E:$E,$A40,'30_NGAN_HANG'!$F:$F,$B40,'30_NGAN_HANG'!$D:$D,"漢字の読み",'30_NGAN_HANG'!$Y:$Y,"Approved") | F40: =COUNTIFS('30_NGAN_HANG'!$E:$E,$A40,'30_NGAN_HANG'!$F:$F,$B40,'30_NGAN_HANG'!$D:$D,"漢字の表記",'30_NGAN_HANG'!$Y:$Y,"Approved") | G40: =COUNTIFS('30_NGAN_HANG'!$E:$E,$A40,'30_NGAN_HANG'!$F:$F,$B40,'30_NGAN_HANG'!$D:$D,"表現",'30_NGAN_HANG'!$Y:$Y,"Approved") | H40: =COUNTIFS('30_NGAN_HANG'!$E:$E,$A40,'30_NGAN_HANG'!$F:$F,$B40,'30_NGAN_HANG'!$D:$D,"文法",'30_NGAN_HANG'!$Y:$Y,"Approved") | I40: =COUNTIFS('30_NGAN_HANG'!$E:$E,$A40,'30_NGAN_HANG'!$F:$F,$B40,'30_NGAN_HANG'!$D:$D,"会話の聴解",'30_NGAN_HANG'!$Y:$Y,"Approved") | J40: =COUNTIFS('30_NGAN_HANG'!$E:$E,$A40,'30_NGAN_HANG'!$F:$F,$B40,'30_NGAN_HANG'!$D:$D,"アナウンス",'30_NGAN_HANG'!$Y:$Y,"Approved") | K40: =COUNTIFS('30_NGAN_HANG'!$E:$E,$A40,'30_NGAN_HANG'!$F:$F,$B40,'30_NGAN_HANG'!$D:$D,"指示の聴解",'30_NGAN_HANG'!$Y:$Y,"Approved") | L40: =COUNTIFS('30_NGAN_HANG'!$E:$E,$A40,'30_NGAN_HANG'!$F:$F,$B40,'30_NGAN_HANG'!$D:$D,"掲示の読解",'30_NGAN_HANG'!$Y:$Y,"Approved") | M40: =COUNTIFS('30_NGAN_HANG'!$E:$E,$A40,'30_NGAN_HANG'!$F:$F,$B40,'30_NGAN_HANG'!$D:$D,"文章の読解",'30_NGAN_HANG'!$Y:$Y,"Approved") | N40: =SUM(C40:M40)
A41: 入門 | B41: 8 | C41: =COUNTIFS('30_NGAN_HANG'!$E:$E,$A41,'30_NGAN_HANG'!$F:$F,$B41,'30_NGAN_HANG'!$D:$D,"語の意味",'30_NGAN_HANG'!$Y:$Y,"Approved") | D41: =COUNTIFS('30_NGAN_HANG'!$E:$E,$A41,'30_NGAN_HANG'!$F:$F,$B41,'30_NGAN_HANG'!$D:$D,"語の使い方",'30_NGAN_HANG'!$Y:$Y,"Approved") | E41: =COUNTIFS('30_NGAN_HANG'!$E:$E,$A41,'30_NGAN_HANG'!$F:$F,$B41,'30_NGAN_HANG'!$D:$D,"漢字の読み",'30_NGAN_HANG'!$Y:$Y,"Approved") | F41: =COUNTIFS('30_NGAN_HANG'!$E:$E,$A41,'30_NGAN_HANG'!$F:$F,$B41,'30_NGAN_HANG'!$D:$D,"漢字の表記",'30_NGAN_HANG'!$Y:$Y,"Approved") | G41: =COUNTIFS('30_NGAN_HANG'!$E:$E,$A41,'30_NGAN_HANG'!$F:$F,$B41,'30_NGAN_HANG'!$D:$D,"表現",'30_NGAN_HANG'!$Y:$Y,"Approved") | H41: =COUNTIFS('30_NGAN_HANG'!$E:$E,$A41,'30_NGAN_HANG'!$F:$F,$B41,'30_NGAN_HANG'!$D:$D,"文法",'30_NGAN_HANG'!$Y:$Y,"Approved") | I41: =COUNTIFS('30_NGAN_HANG'!$E:$E,$A41,'30_NGAN_HANG'!$F:$F,$B41,'30_NGAN_HANG'!$D:$D,"会話の聴解",'30_NGAN_HANG'!$Y:$Y,"Approved") | J41: =COUNTIFS('30_NGAN_HANG'!$E:$E,$A41,'30_NGAN_HANG'!$F:$F,$B41,'30_NGAN_HANG'!$D:$D,"アナウンス",'30_NGAN_HANG'!$Y:$Y,"Approved") | K41: =COUNTIFS('30_NGAN_HANG'!$E:$E,$A41,'30_NGAN_HANG'!$F:$F,$B41,'30_NGAN_HANG'!$D:$D,"指示の聴解",'30_NGAN_HANG'!$Y:$Y,"Approved") | L41: =COUNTIFS('30_NGAN_HANG'!$E:$E,$A41,'30_NGAN_HANG'!$F:$F,$B41,'30_NGAN_HANG'!$D:$D,"掲示の読解",'30_NGAN_HANG'!$Y:$Y,"Approved") | M41: =COUNTIFS('30_NGAN_HANG'!$E:$E,$A41,'30_NGAN_HANG'!$F:$F,$B41,'30_NGAN_HANG'!$D:$D,"文章の読解",'30_NGAN_HANG'!$Y:$Y,"Approved") | N41: =SUM(C41:M41)
A42: 入門 | B42: 9 | C42: =COUNTIFS('30_NGAN_HANG'!$E:$E,$A42,'30_NGAN_HANG'!$F:$F,$B42,'30_NGAN_HANG'!$D:$D,"語の意味",'30_NGAN_HANG'!$Y:$Y,"Approved") | D42: =COUNTIFS('30_NGAN_HANG'!$E:$E,$A42,'30_NGAN_HANG'!$F:$F,$B42,'30_NGAN_HANG'!$D:$D,"語の使い方",'30_NGAN_HANG'!$Y:$Y,"Approved") | E42: =COUNTIFS('30_NGAN_HANG'!$E:$E,$A42,'30_NGAN_HANG'!$F:$F,$B42,'30_NGAN_HANG'!$D:$D,"漢字の読み",'30_NGAN_HANG'!$Y:$Y,"Approved") | F42: =COUNTIFS('30_NGAN_HANG'!$E:$E,$A42,'30_NGAN_HANG'!$F:$F,$B42,'30_NGAN_HANG'!$D:$D,"漢字の表記",'30_NGAN_HANG'!$Y:$Y,"Approved") | G42: =COUNTIFS('30_NGAN_HANG'!$E:$E,$A42,'30_NGAN_HANG'!$F:$F,$B42,'30_NGAN_HANG'!$D:$D,"表現",'30_NGAN_HANG'!$Y:$Y,"Approved") | H42: =COUNTIFS('30_NGAN_HANG'!$E:$E,$A42,'30_NGAN_HANG'!$F:$F,$B42,'30_NGAN_HANG'!$D:$D,"文法",'30_NGAN_HANG'!$Y:$Y,"Approved") | I42: =COUNTIFS('30_NGAN_HANG'!$E:$E,$A42,'30_NGAN_HANG'!$F:$F,$B42,'30_NGAN_HANG'!$D:$D,"会話の聴解",'30_NGAN_HANG'!$Y:$Y,"Approved") | J42: =COUNTIFS('30_NGAN_HANG'!$E:$E,$A42,'30_NGAN_HANG'!$F:$F,$B42,'30_NGAN_HANG'!$D:$D,"アナウンス",'30_NGAN_HANG'!$Y:$Y,"Approved") | K42: =COUNTIFS('30_NGAN_HANG'!$E:$E,$A42,'30_NGAN_HANG'!$F:$F,$B42,'30_NGAN_HANG'!$D:$D,"指示の聴解",'30_NGAN_HANG'!$Y:$Y,"Approved") | L42: =COUNTIFS('30_NGAN_HANG'!$E:$E,$A42,'30_NGAN_HANG'!$F:$F,$B42,'30_NGAN_HANG'!$D:$D,"掲示の読解",'30_NGAN_HANG'!$Y:$Y,"Approved") | M42: =COUNTIFS('30_NGAN_HANG'!$E:$E,$A42,'30_NGAN_HANG'!$F:$F,$B42,'30_NGAN_HANG'!$D:$D,"文章の読解",'30_NGAN_HANG'!$Y:$Y,"Approved") | N42: =SUM(C42:M42)
A43: 入門 | B43: 10 | C43: =COUNTIFS('30_NGAN_HANG'!$E:$E,$A43,'30_NGAN_HANG'!$F:$F,$B43,'30_NGAN_HANG'!$D:$D,"語の意味",'30_NGAN_HANG'!$Y:$Y,"Approved") | D43: =COUNTIFS('30_NGAN_HANG'!$E:$E,$A43,'30_NGAN_HANG'!$F:$F,$B43,'30_NGAN_HANG'!$D:$D,"語の使い方",'30_NGAN_HANG'!$Y:$Y,"Approved") | E43: =COUNTIFS('30_NGAN_HANG'!$E:$E,$A43,'30_NGAN_HANG'!$F:$F,$B43,'30_NGAN_HANG'!$D:$D,"漢字の読み",'30_NGAN_HANG'!$Y:$Y,"Approved") | F43: =COUNTIFS('30_NGAN_HANG'!$E:$E,$A43,'30_NGAN_HANG'!$F:$F,$B43,'30_NGAN_HANG'!$D:$D,"漢字の表記",'30_NGAN_HANG'!$Y:$Y,"Approved") | G43: =COUNTIFS('30_NGAN_HANG'!$E:$E,$A43,'30_NGAN_HANG'!$F:$F,$B43,'30_NGAN_HANG'!$D:$D,"表現",'30_NGAN_HANG'!$Y:$Y,"Approved") | H43: =COUNTIFS('30_NGAN_HANG'!$E:$E,$A43,'30_NGAN_HANG'!$F:$F,$B43,'30_NGAN_HANG'!$D:$D,"文法",'30_NGAN_HANG'!$Y:$Y,"Approved") | I43: =COUNTIFS('30_NGAN_HANG'!$E:$E,$A43,'30_NGAN_HANG'!$F:$F,$B43,'30_NGAN_HANG'!$D:$D,"会話の聴解",'30_NGAN_HANG'!$Y:$Y,"Approved") | J43: =COUNTIFS('30_NGAN_HANG'!$E:$E,$A43,'30_NGAN_HANG'!$F:$F,$B43,'30_NGAN_HANG'!$D:$D,"アナウンス",'30_NGAN_HANG'!$Y:$Y,"Approved") | K43: =COUNTIFS('30_NGAN_HANG'!$E:$E,$A43,'30_NGAN_HANG'!$F:$F,$B43,'30_NGAN_HANG'!$D:$D,"指示の聴解",'30_NGAN_HANG'!$Y:$Y,"Approved") | L43: =COUNTIFS('30_NGAN_HANG'!$E:$E,$A43,'30_NGAN_HANG'!$F:$F,$B43,'30_NGAN_HANG'!$D:$D,"掲示の読解",'30_NGAN_HANG'!$Y:$Y,"Approved") | M43: =COUNTIFS('30_NGAN_HANG'!$E:$E,$A43,'30_NGAN_HANG'!$F:$F,$B43,'30_NGAN_HANG'!$D:$D,"文章の読解",'30_NGAN_HANG'!$Y:$Y,"Approved") | N43: =SUM(C43:M43)
A44: 入門 | B44: 11 | C44: =COUNTIFS('30_NGAN_HANG'!$E:$E,$A44,'30_NGAN_HANG'!$F:$F,$B44,'30_NGAN_HANG'!$D:$D,"語の意味",'30_NGAN_HANG'!$Y:$Y,"Approved") | D44: =COUNTIFS('30_NGAN_HANG'!$E:$E,$A44,'30_NGAN_HANG'!$F:$F,$B44,'30_NGAN_HANG'!$D:$D,"語の使い方",'30_NGAN_HANG'!$Y:$Y,"Approved") | E44: =COUNTIFS('30_NGAN_HANG'!$E:$E,$A44,'30_NGAN_HANG'!$F:$F,$B44,'30_NGAN_HANG'!$D:$D,"漢字の読み",'30_NGAN_HANG'!$Y:$Y,"Approved") | F44: =COUNTIFS('30_NGAN_HANG'!$E:$E,$A44,'30_NGAN_HANG'!$F:$F,$B44,'30_NGAN_HANG'!$D:$D,"漢字の表記",'30_NGAN_HANG'!$Y:$Y,"Approved") | G44: =COUNTIFS('30_NGAN_HANG'!$E:$E,$A44,'30_NGAN_HANG'!$F:$F,$B44,'30_NGAN_HANG'!$D:$D,"表現",'30_NGAN_HANG'!$Y:$Y,"Approved") | H44: =COUNTIFS('30_NGAN_HANG'!$E:$E,$A44,'30_NGAN_HANG'!$F:$F,$B44,'30_NGAN_HANG'!$D:$D,"文法",'30_NGAN_HANG'!$Y:$Y,"Approved") | I44: =COUNTIFS('30_NGAN_HANG'!$E:$E,$A44,'30_NGAN_HANG'!$F:$F,$B44,'30_NGAN_HANG'!$D:$D,"会話の聴解",'30_NGAN_HANG'!$Y:$Y,"Approved") | J44: =COUNTIFS('30_NGAN_HANG'!$E:$E,$A44,'30_NGAN_HANG'!$F:$F,$B44,'30_NGAN_HANG'!$D:$D,"アナウンス",'30_NGAN_HANG'!$Y:$Y,"Approved") | K44: =COUNTIFS('30_NGAN_HANG'!$E:$E,$A44,'30_NGAN_HANG'!$F:$F,$B44,'30_NGAN_HANG'!$D:$D,"指示の聴解",'30_NGAN_HANG'!$Y:$Y,"Approved") | L44: =COUNTIFS('30_NGAN_HANG'!$E:$E,$A44,'30_NGAN_HANG'!$F:$F,$B44,'30_NGAN_HANG'!$D:$D,"掲示の読解",'30_NGAN_HANG'!$Y:$Y,"Approved") | M44: =COUNTIFS('30_NGAN_HANG'!$E:$E,$A44,'30_NGAN_HANG'!$F:$F,$B44,'30_NGAN_HANG'!$D:$D,"文章の読解",'30_NGAN_HANG'!$Y:$Y,"Approved") | N44: =SUM(C44:M44)
...

Sheet 10_NGUON_TU_VUNG
A1: Quyển | B1: Bài | C1: Chủ đề bài | D1: Từ (dạng xuất hiện trong sách) | E1: Cách đọc (hiragana) | F1: Nghĩa tiếng Việt | G1: Từ loại | H1: Nhóm nghĩa | I1: Vẽ hình được? | J1: Từ dễ nhầm | K1: Đã dùng (lần)

Sheet 11_NGUON_KANJI
A1: Quyển | B1: Bài | C1: Chủ đề bài | D1: Kanji | E1: Từ chứa kanji (trong sách) | F1: Cách đọc đúng của từ | G1: Âm On | H1: Âm Kun | I1: Kanji giống hình | J1: Đã dùng (lần)

Sheet 12_NGUON_NGU_PHAP
A1: Quyển | B1: Bài | C1: Chủ đề bài | D1: Mẫu ngữ pháp | E1: Chức năng | F1: Câu ví dụ trong sách | G1: Trợ từ / mẫu dễ nhầm | H1: Đã dùng (lần)

Sheet 13_NGUON_TINH_HUONG
A1: Quyển | B1: Bài | C1: Chủ đề bài | D1: Mã tình huống | E1: Can-do (いろどり) | F1: Địa điểm | G1: Nhân vật / quan hệ | H1: Từ khoá / mẫu câu chính | I1: Dùng cho dạng | J1: Đã dùng (lần)

Sheet IN_01_語の意味
A1: 文字と語彙 › 語の意味 | 1 dòng = 1 yêu cầu sinh câu. Cam = bắt buộc, vàng = gợi ý cho AI.
A2: Mã yêu cầu | B2: Mã đề (kế hoạch) | C2: Quyển | D2: Bài | E2: Số câu cần sinh | F2: Từ đích | G2: Nghĩa tiếng Việt | H2: Kiểu đáp án | I2: Ngữ cảnh câu hỏi | J2: Từ nhiễu gợi ý | K2: Ghi chú cho AI | L2: Công cụ sinh | M2: Người nhập | N2: Trạng thái | O2: Số câu đã sinh | P2: Số câu Approved
A3: IN_01-0001 | C3: 入門 | D3: 1 | E3: 3 | F3: 会社 | G3: công ty | H3: Hình 4 ô | I3: わたしの ___ は 大きいです。 | J3: 学校;病院;銀行 | K3: VÍ DỤ — xoá dòng này khi dùng thật | L3: ChatGPT | N3: Nháp | O3: =IF(A3="","",COUNTIF('30_NGAN_HANG'!$B:$B,A3)) | P3: =IF(A3="","",COUNTIFS('30_NGAN_HANG'!$B:$B,A3,'30_NGAN_HANG'!$Y:$Y,"Approved"))
O4: =IF(A4="","",COUNTIF('30_NGAN_HANG'!$B:$B,A4)) | P4: =IF(A4="","",COUNTIFS('30_NGAN_HANG'!$B:$B,A4,'30_NGAN_HANG'!$Y:$Y,"Approved"))
O5: =IF(A5="","",COUNTIF('30_NGAN_HANG'!$B:$B,A5)) | P5: =IF(A5="","",COUNTIFS('30_NGAN_HANG'!$B:$B,A5,'30_NGAN_HANG'!$Y:$Y,"Approved"))
O6: =IF(A6="","",COUNTIF('30_NGAN_HANG'!$B:$B,A6)) | P6: =IF(A6="","",COUNTIFS('30_NGAN_HANG'!$B:$B,A6,'30_NGAN_HANG'!$Y:$Y,"Approved"))
O7: =IF(A7="","",COUNTIF('30_NGAN_HANG'!$B:$B,A7)) | P7: =IF(A7="","",COUNTIFS('30_NGAN_HANG'!$B:$B,A7,'30_NGAN_HANG'!$Y:$Y,"Approved"))
O8: =IF(A8="","",COUNTIF('30_NGAN_HANG'!$B:$B,A8)) | P8: =IF(A8="","",COUNTIFS('30_NGAN_HANG'!$B:$B,A8,'30_NGAN_HANG'!$Y:$Y,"Approved"))
O9: =IF(A9="","",COUNTIF('30_NGAN_HANG'!$B:$B,A9)) | P9: =IF(A9="","",COUNTIFS('30_NGAN_HANG'!$B:$B,A9,'30_NGAN_HANG'!$Y:$Y,"Approved"))
O10: =IF(A10="","",COUNTIF('30_NGAN_HANG'!$B:$B,A10)) | P10: =IF(A10="","",COUNTIFS('30_NGAN_HANG'!$B:$B,A10,'30_NGAN_HANG'!$Y:$Y,"Approved"))
O11: =IF(A11="","",COUNTIF('30_NGAN_HANG'!$B:$B,A11)) | P11: =IF(A11="","",COUNTIFS('30_NGAN_HANG'!$B:$B,A11,'30_NGAN_HANG'!$Y:$Y,"Approved"))
O12: =IF(A12="","",COUNTIF('30_NGAN_HANG'!$B:$B,A12)) | P12: =IF(A12="","",COUNTIFS('30_NGAN_HANG'!$B:$B,A12,'30_NGAN_HANG'!$Y:$Y,"Approved"))
O13: =IF(A13="","",COUNTIF('30_NGAN_HANG'!$B:$B,A13)) | P13: =IF(A13="","",COUNTIFS('30_NGAN_HANG'!$B:$B,A13,'30_NGAN_HANG'!$Y:$Y,"Approved"))
O14: =IF(A14="","",COUNTIF('30_NGAN_HANG'!$B:$B,A14)) | P14: =IF(A14="","",COUNTIFS('30_NGAN_HANG'!$B:$B,A14,'30_NGAN_HANG'!$Y:$Y,"Approved"))
O15: =IF(A15="","",COUNTIF('30_NGAN_HANG'!$B:$B,A15)) | P15: =IF(A15="","",COUNTIFS('30_NGAN_HANG'!$B:$B,A15,'30_NGAN_HANG'!$Y:$Y,"Approved"))
... O300: =IF(A300="","",COUNTIF('30_NGAN_HANG'!$B:$B,A300)) | P300: =IF(A300="","",COUNTIFS('30_NGAN_HANG'!$B:$B,A300,'30_NGAN_HANG'!$Y:$Y,"Approved"))

Sheet IN_02_語の使い方
A1: 文字と語彙 › 語の使い方 | 1 dòng = 1 yêu cầu sinh câu. Cam = bắt buộc, vàng = gợi ý cho AI.
A2: Mã yêu cầu | B2: Mã đề (kế hoạch) | C2: Quyển | D2: Bài | E2: Số câu cần sinh | F2: Từ đích | G2: Câu ngữ cảnh (có ___) | H2: Collocation đúng | I2: Lỗi dùng từ muốn bẫy | J2: Ghi chú cho AI | K2: Công cụ sinh | L2: Người nhập | M2: Trạng thái | N2: Số câu đã sinh | O2: Số câu Approved
A3: IN_02-0001 | C3: 入門 | D3: 1 | E3: 3 | F3: かける | G3: 友だちに 電話を ___。 | H3: 電話を かける | I3: する;とる;いう | J3: VÍ DỤ — xoá dòng này khi dùng thật | K3: ChatGPT | M3: Nháp | N3: =IF(A3="","",COUNTIF('30_NGAN_HANG'!$B:$B,A3)) | O3: =IF(A3="","",COUNTIFS('30_NGAN_HANG'!$B:$B,A3,'30_NGAN_HANG'!$Y:$Y,"Approved"))
N4: =IF(A4="","",COUNTIF('30_NGAN_HANG'!$B:$B,A4)) | O4: =IF(A4="","",COUNTIFS('30_NGAN_HANG'!$B:$B,A4,'30_NGAN_HANG'!$Y:$Y,"Approved"))
N5: =IF(A5="","",COUNTIF('30_NGAN_HANG'!$B:$B,A5)) | O5: =IF(A5="","",COUNTIFS('30_NGAN_HANG'!$B:$B,A5,'30_NGAN_HANG'!$Y:$Y,"Approved"))
N6: =IF(A6="","",COUNTIF('30_NGAN_HANG'!$B:$B,A6)) | O6: =IF(A6="","",COUNTIFS('30_NGAN_HANG'!$B:$B,A6,'30_NGAN_HANG'!$Y:$Y,"Approved"))
N7: =IF(A7="","",COUNTIF('30_NGAN_HANG'!$B:$B,A7)) | O7: =IF(A7="","",COUNTIFS('30_NGAN_HANG'!$B:$B,A7,'30_NGAN_HANG'!$Y:$Y,"Approved"))
N8: =IF(A8="","",COUNTIF('30_NGAN_HANG'!$B:$B,A8)) | O8: =IF(A8="","",COUNTIFS('30_NGAN_HANG'!$B:$B,A8,'30_NGAN_HANG'!$Y:$Y,"Approved"))
N9: =IF(A9="","",COUNTIF('30_NGAN_HANG'!$B:$B,A9)) | O9: =IF(A9="","",COUNTIFS('30_NGAN_HANG'!$B:$B,A9,'30_NGAN_HANG'!$Y:$Y,"Approved"))
N10: =IF(A10="","",COUNTIF('30_NGAN_HANG'!$B:$B,A10)) | O10: =IF(A10="","",COUNTIFS('30_NGAN_HANG'!$B:$B,A10,'30_NGAN_HANG'!$Y:$Y,"Approved"))
N11: =IF(A11="","",COUNTIF('30_NGAN_HANG'!$B:$B,A11)) | O11: =IF(A11="","",COUNTIFS('30_NGAN_HANG'!$B:$B,A11,'30_NGAN_HANG'!$Y:$Y,"Approved"))
N12: =IF(A12="","",COUNTIF('30_NGAN_HANG'!$B:$B,A12)) | O12: =IF(A12="","",COUNTIFS('30_NGAN_HANG'!$B:$B,A12,'30_NGAN_HANG'!$Y:$Y,"Approved"))
N13: =IF(A13="","",COUNTIF('30_NGAN_HANG'!$B:$B,A13)) | O13: =IF(A13="","",COUNTIFS('30_NGAN_HANG'!$B:$B,A13,'30_NGAN_HANG'!$Y:$Y,"Approved"))
N14: =IF(A14="","",COUNTIF('30_NGAN_HANG'!$B:$B,A14)) | O14: =IF(A14="","",COUNTIFS('30_NGAN_HANG'!$B:$B,A14,'30_NGAN_HANG'!$Y:$Y,"Approved"))
N15: =IF(A15="","",COUNTIF('30_NGAN_HANG'!$B:$B,A15)) | O15: =IF(A15="","",COUNTIFS('30_NGAN_HANG'!$B:$B,A15,'30_NGAN_HANG'!$Y:$Y,"Approved"))
... N300: =IF(A300="","",COUNTIF('30_NGAN_HANG'!$B:$B,A300)) | O300: =IF(A300="","",COUNTIFS('30_NGAN_HANG'!$B:$B,A300,'30_NGAN_HANG'!$Y:$Y,"Approved"))

Sheet IN_03_漢字の読み
A1: 文字と語彙 › 漢字の読み | 1 dòng = 1 yêu cầu sinh câu. Cam = bắt buộc, vàng = gợi ý cho AI.
A2: Mã yêu cầu | B2: Mã đề (kế hoạch) | C2: Quyển | D2: Bài | E2: Số câu cần sinh | F2: Từ chứa kanji (gạch chân) | G2: Cách đọc đúng | H2: Câu ngữ cảnh | I2: Kiểu nhiễu | J2: Ghi chú cho AI | K2: Công cụ sinh | L2: Người nhập | M2: Trạng thái | N2: Số câu đã sinh | O2: Số câu Approved
A3: IN_03-0001 | C3: 入門 | D3: 1 | E3: 3 | F3: 会社 | G3: かいしゃ | H3: あした 会社に 行きます。 | I3: Trường âm;Âm đục | J3: VÍ DỤ — xoá dòng này khi dùng thật | K3: ChatGPT | M3: Nháp | N3: =IF(A3="","",COUNTIF('30_NGAN_HANG'!$B:$B,A3)) | O3: =IF(A3="","",COUNTIFS('30_NGAN_HANG'!$B:$B,A3,'30_NGAN_HANG'!$Y:$Y,"Approved"))
N4: =IF(A4="","",COUNTIF('30_NGAN_HANG'!$B:$B,A4)) | O4: =IF(A4="","",COUNTIFS('30_NGAN_HANG'!$B:$B,A4,'30_NGAN_HANG'!$Y:$Y,"Approved"))
N5: =IF(A5="","",COUNTIF('30_NGAN_HANG'!$B:$B,A5)) | O5: =IF(A5="","",COUNTIFS('30_NGAN_HANG'!$B:$B,A5,'30_NGAN_HANG'!$Y:$Y,"Approved"))
N6: =IF(A6="","",COUNTIF('30_NGAN_HANG'!$B:$B,A6)) | O6: =IF(A6="","",COUNTIFS('30_NGAN_HANG'!$B:$B,A6,'30_NGAN_HANG'!$Y:$Y,"Approved"))
N7: =IF(A7="","",COUNTIF('30_NGAN_HANG'!$B:$B,A7)) | O7: =IF(A7="","",COUNTIFS('30_NGAN_HANG'!$B:$B,A7,'30_NGAN_HANG'!$Y:$Y,"Approved"))
N8: =IF(A8="","",COUNTIF('30_NGAN_HANG'!$B:$B,A8)) | O8: =IF(A8="","",COUNTIFS('30_NGAN_HANG'!$B:$B,A8,'30_NGAN_HANG'!$Y:$Y,"Approved"))
N9: =IF(A9="","",COUNTIF('30_NGAN_HANG'!$B:$B,A9)) | O9: =IF(A9="","",COUNTIFS('30_NGAN_HANG'!$B:$B,A9,'30_NGAN_HANG'!$Y:$Y,"Approved"))
N10: =IF(A10="","",COUNTIF('30_NGAN_HANG'!$B:$B,A10)) | O10: =IF(A10="","",COUNTIFS('30_NGAN_HANG'!$B:$B,A10,'30_NGAN_HANG'!$Y:$Y,"Approved"))
N11: =IF(A11="","",COUNTIF('30_NGAN_HANG'!$B:$B,A11)) | O11: =IF(A11="","",COUNTIFS('30_NGAN_HANG'!$B:$B,A11,'30_NGAN_HANG'!$Y:$Y,"Approved"))
N12: =IF(A12="","",COUNTIF('30_NGAN_HANG'!$B:$B,A12)) | O12: =IF(A12="","",COUNTIFS('30_NGAN_HANG'!$B:$B,A12,'30_NGAN_HANG'!$Y:$Y,"Approved"))
N13: =IF(A13="","",COUNTIF('30_NGAN_HANG'!$B:$B,A13)) | O13: =IF(A13="","",COUNTIFS('30_NGAN_HANG'!$B:$B,A13,'30_NGAN_HANG'!$Y:$Y,"Approved"))
N14: =IF(A14="","",COUNTIF('30_NGAN_HANG'!$B:$B,A14)) | O14: =IF(A14="","",COUNTIFS('30_NGAN_HANG'!$B:$B,A14,'30_NGAN_HANG'!$Y:$Y,"Approved"))
N15: =IF(A15="","",COUNTIF('30_NGAN_HANG'!$B:$B,A15)) | O15: =IF(A15="","",COUNTIFS('30_NGAN_HANG'!$B:$B,A15,'30_NGAN_HANG'!$Y:$Y,"Approved"))
... N300: =IF(A300="","",COUNTIF('30_NGAN_HANG'!$B:$B,A300)) | O300: =IF(A300="","",COUNTIFS('30_NGAN_HANG'!$B:$B,A300,'30_NGAN_HANG'!$Y:$Y,"Approved"))

Sheet IN_04_漢字の表記
A1: 文字と語彙 › 漢字の表記 | 1 dòng = 1 yêu cầu sinh câu. Cam = bắt buộc, vàng = gợi ý cho AI.
A2: Mã yêu cầu | B2: Mã đề (kế hoạch) | C2: Quyển | D2: Bài | E2: Số câu cần sinh | F2: Từ viết hiragana (gạch chân) | G2: Kanji đúng | H2: Câu ngữ cảnh | I2: Kanji nhiễu | J2: Ghi chú cho AI | K2: Công cụ sinh | L2: Người nhập | M2: Trạng thái | N2: Số câu đã sinh | O2: Số câu Approved
A3: IN_04-0001 | C3: 入門 | D3: 1 | E3: 3 | F3: やすみ | G3: 休み | H3: あしたは やすみです。 | I3: 体み;休見;安み | J3: VÍ DỤ — xoá dòng này khi dùng thật | K3: ChatGPT | M3: Nháp | N3: =IF(A3="","",COUNTIF('30_NGAN_HANG'!$B:$B,A3)) | O3: =IF(A3="","",COUNTIFS('30_NGAN_HANG'!$B:$B,A3,'30_NGAN_HANG'!$Y:$Y,"Approved"))
N4: =IF(A4="","",COUNTIF('30_NGAN_HANG'!$B:$B,A4)) | O4: =IF(A4="","",COUNTIFS('30_NGAN_HANG'!$B:$B,A4,'30_NGAN_HANG'!$Y:$Y,"Approved"))
N5: =IF(A5="","",COUNTIF('30_NGAN_HANG'!$B:$B,A5)) | O5: =IF(A5="","",COUNTIFS('30_NGAN_HANG'!$B:$B,A5,'30_NGAN_HANG'!$Y:$Y,"Approved"))
N6: =IF(A6="","",COUNTIF('30_NGAN_HANG'!$B:$B,A6)) | O6: =IF(A6="","",COUNTIFS('30_NGAN_HANG'!$B:$B,A6,'30_NGAN_HANG'!$Y:$Y,"Approved"))
N7: =IF(A7="","",COUNTIF('30_NGAN_HANG'!$B:$B,A7)) | O7: =IF(A7="","",COUNTIFS('30_NGAN_HANG'!$B:$B,A7,'30_NGAN_HANG'!$Y:$Y,"Approved"))
N8: =IF(A8="","",COUNTIF('30_NGAN_HANG'!$B:$B,A8)) | O8: =IF(A8="","",COUNTIFS('30_NGAN_HANG'!$B:$B,A8,'30_NGAN_HANG'!$Y:$Y,"Approved"))
N9: =IF(A9="","",COUNTIF('30_NGAN_HANG'!$B:$B,A9)) | O9: =IF(A9="","",COUNTIFS('30_NGAN_HANG'!$B:$B,A9,'30_NGAN_HANG'!$Y:$Y,"Approved"))
N10: =IF(A10="","",COUNTIF('30_NGAN_HANG'!$B:$B,A10)) | O10: =IF(A10="","",COUNTIFS('30_NGAN_HANG'!$B:$B,A10,'30_NGAN_HANG'!$Y:$Y,"Approved"))
N11: =IF(A11="","",COUNTIF('30_NGAN_HANG'!$B:$B,A11)) | O11: =IF(A11="","",COUNTIFS('30_NGAN_HANG'!$B:$B,A11,'30_NGAN_HANG'!$Y:$Y,"Approved"))
N12: =IF(A12="","",COUNTIF('30_NGAN_HANG'!$B:$B,A12)) | O12: =IF(A12="","",COUNTIFS('30_NGAN_HANG'!$B:$B,A12,'30_NGAN_HANG'!$Y:$Y,"Approved"))
N13: =IF(A13="","",COUNTIF('30_NGAN_HANG'!$B:$B,A13)) | O13: =IF(A13="","",COUNTIFS('30_NGAN_HANG'!$B:$B,A13,'30_NGAN_HANG'!$Y:$Y,"Approved"))
N14: =IF(A14="","",COUNTIF('30_NGAN_HANG'!$B:$B,A14)) | O14: =IF(A14="","",COUNTIFS('30_NGAN_HANG'!$B:$B,A14,'30_NGAN_HANG'!$Y:$Y,"Approved"))
N15: =IF(A15="","",COUNTIF('30_NGAN_HANG'!$B:$B,A15)) | O15: =IF(A15="","",COUNTIFS('30_NGAN_HANG'!$B:$B,A15,'30_NGAN_HANG'!$Y:$Y,"Approved"))
... N300: =IF(A300="","",COUNTIF('30_NGAN_HANG'!$B:$B,A300)) | O300: =IF(A300="","",COUNTIFS('30_NGAN_HANG'!$B:$B,A300,'30_NGAN_HANG'!$Y:$Y,"Approved"))

Sheet IN_05_表現
A1: 会話と表現 › 表現 | 1 dòng = 1 yêu cầu sinh câu. Cam = bắt buộc, vàng = gợi ý cho AI.
A2: Mã yêu cầu | B2: Mã đề (kế hoạch) | C2: Quyển | D2: Bài | E2: Số câu cần sinh | F2: Mã tình huống | G2: Chức năng giao tiếp | H2: Người nói → người nghe | I2: Mức lịch sự | J2: Mô tả tình huống (VN hoặc JP) | K2: Câu đúng mong muốn | L2: Câu nhiễu gợi ý | M2: Ghi chú cho AI | N2: Công cụ sinh | O2: Người nhập | P2: Trạng thái | Q2: Số câu đã sinh | R2: Số câu Approved
A3: IN_05-0001 | C3: 入門 | D3: 1 | E3: 3 | F3: TH-VÍ DỤ | G3: Xin phép về trước | H3: nhân viên → sếp | I3: です・ます | J3: Hết giờ làm, muốn về trước sếp | K3: お先に失礼します。 | L3: お疲れさまでした。;いってきます。 | M3: VÍ DỤ — xoá dòng này khi dùng thật | N3: ChatGPT | P3: Nháp | Q3: =IF(A3="","",COUNTIF('30_NGAN_HANG'!$B:$B,A3)) | R3: =IF(A3="","",COUNTIFS('30_NGAN_HANG'!$B:$B,A3,'30_NGAN_HANG'!$Y:$Y,"Approved"))
Q4: =IF(A4="","",COUNTIF('30_NGAN_HANG'!$B:$B,A4)) | R4: =IF(A4="","",COUNTIFS('30_NGAN_HANG'!$B:$B,A4,'30_NGAN_HANG'!$Y:$Y,"Approved"))
Q5: =IF(A5="","",COUNTIF('30_NGAN_HANG'!$B:$B,A5)) | R5: =IF(A5="","",COUNTIFS('30_NGAN_HANG'!$B:$B,A5,'30_NGAN_HANG'!$Y:$Y,"Approved"))
Q6: =IF(A6="","",COUNTIF('30_NGAN_HANG'!$B:$B,A6)) | R6: =IF(A6="","",COUNTIFS('30_NGAN_HANG'!$B:$B,A6,'30_NGAN_HANG'!$Y:$Y,"Approved"))
Q7: =IF(A7="","",COUNTIF('30_NGAN_HANG'!$B:$B,A7)) | R7: =IF(A7="","",COUNTIFS('30_NGAN_HANG'!$B:$B,A7,'30_NGAN_HANG'!$Y:$Y,"Approved"))
Q8: =IF(A8="","",COUNTIF('30_NGAN_HANG'!$B:$B,A8)) | R8: =IF(A8="","",COUNTIFS('30_NGAN_HANG'!$B:$B,A8,'30_NGAN_HANG'!$Y:$Y,"Approved"))
Q9: =IF(A9="","",COUNTIF('30_NGAN_HANG'!$B:$B,A9)) | R9: =IF(A9="","",COUNTIFS('30_NGAN_HANG'!$B:$B,A9,'30_NGAN_HANG'!$Y:$Y,"Approved"))
Q10: =IF(A10="","",COUNTIF('30_NGAN_HANG'!$B:$B,A10)) | R10: =IF(A10="","",COUNTIFS('30_NGAN_HANG'!$B:$B,A10,'30_NGAN_HANG'!$Y:$Y,"Approved"))
Q11: =IF(A11="","",COUNTIF('30_NGAN_HANG'!$B:$B,A11)) | R11: =IF(A11="","",COUNTIFS('30_NGAN_HANG'!$B:$B,A11,'30_NGAN_HANG'!$Y:$Y,"Approved"))
Q12: =IF(A12="","",COUNTIF('30_NGAN_HANG'!$B:$B,A12)) | R12: =IF(A12="","",COUNTIFS('30_NGAN_HANG'!$B:$B,A12,'30_NGAN_HANG'!$Y:$Y,"Approved"))
Q13: =IF(A13="","",COUNTIF('30_NGAN_HANG'!$B:$B,A13)) | R13: =IF(A13="","",COUNTIFS('30_NGAN_HANG'!$B:$B,A13,'30_NGAN_HANG'!$Y:$Y,"Approved"))
Q14: =IF(A14="","",COUNTIF('30_NGAN_HANG'!$B:$B,A14)) | R14: =IF(A14="","",COUNTIFS('30_NGAN_HANG'!$B:$B,A14,'30_NGAN_HANG'!$Y:$Y,"Approved"))
Q15: =IF(A15="","",COUNTIF('30_NGAN_HANG'!$B:$B,A15)) | R15: =IF(A15="","",COUNTIFS('30_NGAN_HANG'!$B:$B,A15,'30_NGAN_HANG'!$Y:$Y,"Approved"))
... Q300: =IF(A300="","",COUNTIF('30_NGAN_HANG'!$B:$B,A300)) | R300: =IF(A300="","",COUNTIFS('30_NGAN_HANG'!$B:$B,A300,'30_NGAN_HANG'!$Y:$Y,"Approved"))

Sheet IN_06_文法
A1: 会話と表現 › 文法 | 1 dòng = 1 yêu cầu sinh câu. Cam = bắt buộc, vàng = gợi ý cho AI.
A2: Mã yêu cầu | B2: Mã đề (kế hoạch) | C2: Quyển | D2: Bài | E2: Số câu cần sinh | F2: Mẫu ngữ pháp đích | G2: Dạng câu | H2: Ngữ cảnh | I2: Vị trí ô trống | J2: Mẫu dễ nhầm làm nhiễu | K2: Ghi chú cho AI | L2: Công cụ sinh | M2: Người nhập | N2: Trạng thái | O2: Số câu đã sinh | P2: Số câu Approved
A3: IN_06-0001 | C3: 入門 | D3: 1 | E3: 3 | F3: 〜てください | G3: Hội thoại A-B | H3: Ở văn phòng, sếp nhờ nhân viên | I3: Đuôi động từ | J3: 〜てもいいです;〜ています | K3: VÍ DỤ — xoá dòng này khi dùng thật | L3: ChatGPT | N3: Nháp | O3: =IF(A3="","",COUNTIF('30_NGAN_HANG'!$B:$B,A3)) | P3: =IF(A3="","",COUNTIFS('30_NGAN_HANG'!$B:$B,A3,'30_NGAN_HANG'!$Y:$Y,"Approved"))
O4: =IF(A4="","",COUNTIF('30_NGAN_HANG'!$B:$B,A4)) | P4: =IF(A4="","",COUNTIFS('30_NGAN_HANG'!$B:$B,A4,'30_NGAN_HANG'!$Y:$Y,"Approved"))
O5: =IF(A5="","",COUNTIF('30_NGAN_HANG'!$B:$B,A5)) | P5: =IF(A5="","",COUNTIFS('30_NGAN_HANG'!$B:$B,A5,'30_NGAN_HANG'!$Y:$Y,"Approved"))
O6: =IF(A6="","",COUNTIF('30_NGAN_HANG'!$B:$B,A6)) | P6: =IF(A6="","",COUNTIFS('30_NGAN_HANG'!$B:$B,A6,'30_NGAN_HANG'!$Y:$Y,"Approved"))
O7: =IF(A7="","",COUNTIF('30_NGAN_HANG'!$B:$B,A7)) | P7: =IF(A7="","",COUNTIFS('30_NGAN_HANG'!$B:$B,A7,'30_NGAN_HANG'!$Y:$Y,"Approved"))
O8: =IF(A8="","",COUNTIF('30_NGAN_HANG'!$B:$B,A8)) | P8: =IF(A8="","",COUNTIFS('30_NGAN_HANG'!$B:$B,A8,'30_NGAN_HANG'!$Y:$Y,"Approved"))
O9: =IF(A9="","",COUNTIF('30_NGAN_HANG'!$B:$B,A9)) | P9: =IF(A9="","",COUNTIFS('30_NGAN_HANG'!$B:$B,A9,'30_NGAN_HANG'!$Y:$Y,"Approved"))
O10: =IF(A10="","",COUNTIF('30_NGAN_HANG'!$B:$B,A10)) | P10: =IF(A10="","",COUNTIFS('30_NGAN_HANG'!$B:$B,A10,'30_NGAN_HANG'!$Y:$Y,"Approved"))
O11: =IF(A11="","",COUNTIF('30_NGAN_HANG'!$B:$B,A11)) | P11: =IF(A11="","",COUNTIFS('30_NGAN_HANG'!$B:$B,A11,'30_NGAN_HANG'!$Y:$Y,"Approved"))
O12: =IF(A12="","",COUNTIF('30_NGAN_HANG'!$B:$B,A12)) | P12: =IF(A12="","",COUNTIFS('30_NGAN_HANG'!$B:$B,A12,'30_NGAN_HANG'!$Y:$Y,"Approved"))
O13: =IF(A13="","",COUNTIF('30_NGAN_HANG'!$B:$B,A13)) | P13: =IF(A13="","",COUNTIFS('30_NGAN_HANG'!$B:$B,A13,'30_NGAN_HANG'!$Y:$Y,"Approved"))
O14: =IF(A14="","",COUNTIF('30_NGAN_HANG'!$B:$B,A14)) | P14: =IF(A14="","",COUNTIFS('30_NGAN_HANG'!$B:$B,A14,'30_NGAN_HANG'!$Y:$Y,"Approved"))
O15: =IF(A15="","",COUNTIF('30_NGAN_HANG'!$B:$B,A15)) | P15: =IF(A15="","",COUNTIFS('30_NGAN_HANG'!$B:$B,A15,'30_NGAN_HANG'!$Y:$Y,"Approved"))
... O300: =IF(A300="","",COUNTIF('30_NGAN_HANG'!$B:$B,A300)) | P300: =IF(A300="","",COUNTIFS('30_NGAN_HANG'!$B:$B,A300,'30_NGAN_HANG'!$Y:$Y,"Approved"))

Sheet IN_07_会話の聴解
A1: 聴解 › 会話の聴解 | 1 dòng = 1 yêu cầu sinh câu. Cam = bắt buộc, vàng = gợi ý cho AI.
A2: Mã yêu cầu | B2: Mã đề (kế hoạch) | C2: Quyển | D2: Bài | E2: Số câu cần sinh | F2: Mã tình huống | G2: Địa điểm | H2: Người nói | I2: Câu hỏi trọng tâm | J2: Kiểu đáp án | K2: Thông tin bẫy | L2: Số lượt thoại | M2: Từ vựng/ngữ pháp bắt buộc dùng | N2: Ghi chú cho AI | O2: Công cụ sinh | P2: Người nhập | Q2: Trạng thái | R2: Số câu đã sinh | S2: Số câu Approved
A3: IN_07-0001 | C3: 入門 | D3: 1 | E3: 3 | F3: TH-VÍ DỤ | G3: Cửa hàng tiện lợi | H3: F=nhân viên; M=khách | I3: Khách mua gì? | J3: Hình 4 ô | K3: Định mua cơm hộp nhưng đổi sang bánh mì | L3: 6 | M3: おにぎり;パン | N3: VÍ DỤ — xoá dòng này khi dùng thật | O3: ChatGPT | Q3: Nháp | R3: =IF(A3="","",COUNTIF('30_NGAN_HANG'!$B:$B,A3)) | S3: =IF(A3="","",COUNTIFS('30_NGAN_HANG'!$B:$B,A3,'30_NGAN_HANG'!$Y:$Y,"Approved"))
R4: =IF(A4="","",COUNTIF('30_NGAN_HANG'!$B:$B,A4)) | S4: =IF(A4="","",COUNTIFS('30_NGAN_HANG'!$B:$B,A4,'30_NGAN_HANG'!$Y:$Y,"Approved"))
R5: =IF(A5="","",COUNTIF('30_NGAN_HANG'!$B:$B,A5)) | S5: =IF(A5="","",COUNTIFS('30_NGAN_HANG'!$B:$B,A5,'30_NGAN_HANG'!$Y:$Y,"Approved"))
R6: =IF(A6="","",COUNTIF('30_NGAN_HANG'!$B:$B,A6)) | S6: =IF(A6="","",COUNTIFS('30_NGAN_HANG'!$B:$B,A6,'30_NGAN_HANG'!$Y:$Y,"Approved"))
R7: =IF(A7="","",COUNTIF('30_NGAN_HANG'!$B:$B,A7)) | S7: =IF(A7="","",COUNTIFS('30_NGAN_HANG'!$B:$B,A7,'30_NGAN_HANG'!$Y:$Y,"Approved"))
R8: =IF(A8="","",COUNTIF('30_NGAN_HANG'!$B:$B,A8)) | S8: =IF(A8="","",COUNTIFS('30_NGAN_HANG'!$B:$B,A8,'30_NGAN_HANG'!$Y:$Y,"Approved"))
R9: =IF(A9="","",COUNTIF('30_NGAN_HANG'!$B:$B,A9)) | S9: =IF(A9="","",COUNTIFS('30_NGAN_HANG'!$B:$B,A9,'30_NGAN_HANG'!$Y:$Y,"Approved"))
R10: =IF(A10="","",COUNTIF('30_NGAN_HANG'!$B:$B,A10)) | S10: =IF(A10="","",COUNTIFS('30_NGAN_HANG'!$B:$B,A10,'30_NGAN_HANG'!$Y:$Y,"Approved"))
R11: =IF(A11="","",COUNTIF('30_NGAN_HANG'!$B:$B,A11)) | S11: =IF(A11="","",COUNTIFS('30_NGAN_HANG'!$B:$B,A11,'30_NGAN_HANG'!$Y:$Y,"Approved"))
R12: =IF(A12="","",COUNTIF('30_NGAN_HANG'!$B:$B,A12)) | S12: =IF(A12="","",COUNTIFS('30_NGAN_HANG'!$B:$B,A12,'30_NGAN_HANG'!$Y:$Y,"Approved"))
R13: =IF(A13="","",COUNTIF('30_NGAN_HANG'!$B:$B,A13)) | S13: =IF(A13="","",COUNTIFS('30_NGAN_HANG'!$B:$B,A13,'30_NGAN_HANG'!$Y:$Y,"Approved"))
R14: =IF(A14="","",COUNTIF('30_NGAN_HANG'!$B:$B,A14)) | S14: =IF(A14="","",COUNTIFS('30_NGAN_HANG'!$B:$B,A14,'30_NGAN_HANG'!$Y:$Y,"Approved"))
R15: =IF(A15="","",COUNTIF('30_NGAN_HANG'!$B:$B,A15)) | S15: =IF(A15="","",COUNTIFS('30_NGAN_HANG'!$B:$B,A15,'30_NGAN_HANG'!$Y:$Y,"Approved"))
... R300: =IF(A300="","",COUNTIF('30_NGAN_HANG'!$B:$B,A300)) | S300: =IF(A300="","",COUNTIFS('30_NGAN_HANG'!$B:$B,A300,'30_NGAN_HANG'!$Y:$Y,"Approved"))

Sheet IN_08_アナウンス
A1: 聴解 › アナウンス | 1 dòng = 1 yêu cầu sinh câu. Cam = bắt buộc, vàng = gợi ý cho AI.
A2: Mã yêu cầu | B2: Mã đề (kế hoạch) | C2: Quyển | D2: Bài | E2: Số câu cần sinh | F2: Địa điểm | G2: Loại thông báo | H2: Thông tin cần nghe | I2: Giọng | J2: Thông tin bẫy | K2: Độ dài (giây) | L2: Ghi chú cho AI | M2: Công cụ sinh | N2: Người nhập | O2: Trạng thái | P2: Số câu đã sinh | Q2: Số câu Approved
A3: IN_08-0001 | C3: 入門 | D3: 1 | E3: 3 | F3: Ga tàu | G3: Tàu trễ | H3: Tàu đến lúc mấy giờ | I3: F | J3: Giờ cũ được nhắc trước giờ mới | K3: 25 | L3: VÍ DỤ — xoá dòng này khi dùng thật | M3: ChatGPT | O3: Nháp | P3: =IF(A3="","",COUNTIF('30_NGAN_HANG'!$B:$B,A3)) | Q3: =IF(A3="","",COUNTIFS('30_NGAN_HANG'!$B:$B,A3,'30_NGAN_HANG'!$Y:$Y,"Approved"))
P4: =IF(A4="","",COUNTIF('30_NGAN_HANG'!$B:$B,A4)) | Q4: =IF(A4="","",COUNTIFS('30_NGAN_HANG'!$B:$B,A4,'30_NGAN_HANG'!$Y:$Y,"Approved"))
P5: =IF(A5="","",COUNTIF('30_NGAN_HANG'!$B:$B,A5)) | Q5: =IF(A5="","",COUNTIFS('30_NGAN_HANG'!$B:$B,A5,'30_NGAN_HANG'!$Y:$Y,"Approved"))
P6: =IF(A6="","",COUNTIF('30_NGAN_HANG'!$B:$B,A6)) | Q6: =IF(A6="","",COUNTIFS('30_NGAN_HANG'!$B:$B,A6,'30_NGAN_HANG'!$Y:$Y,"Approved"))
P7: =IF(A7="","",COUNTIF('30_NGAN_HANG'!$B:$B,A7)) | Q7: =IF(A7="","",COUNTIFS('30_NGAN_HANG'!$B:$B,A7,'30_NGAN_HANG'!$Y:$Y,"Approved"))
P8: =IF(A8="","",COUNTIF('30_NGAN_HANG'!$B:$B,A8)) | Q8: =IF(A8="","",COUNTIFS('30_NGAN_HANG'!$B:$B,A8,'30_NGAN_HANG'!$Y:$Y,"Approved"))
P9: =IF(A9="","",COUNTIF('30_NGAN_HANG'!$B:$B,A9)) | Q9: =IF(A9="","",COUNTIFS('30_NGAN_HANG'!$B:$B,A9,'30_NGAN_HANG'!$Y:$Y,"Approved"))
P10: =IF(A10="","",COUNTIF('30_NGAN_HANG'!$B:$B,A10)) | Q10: =IF(A10="","",COUNTIFS('30_NGAN_HANG'!$B:$B,A10,'30_NGAN_HANG'!$Y:$Y,"Approved"))
P11: =IF(A11="","",COUNTIF('30_NGAN_HANG'!$B:$B,A11)) | Q11: =IF(A11="","",COUNTIFS('30_NGAN_HANG'!$B:$B,A11,'30_NGAN_HANG'!$Y:$Y,"Approved"))
P12: =IF(A12="","",COUNTIF('30_NGAN_HANG'!$B:$B,A12)) | Q12: =IF(A12="","",COUNTIFS('30_NGAN_HANG'!$B:$B,A12,'30_NGAN_HANG'!$Y:$Y,"Approved"))
P13: =IF(A13="","",COUNTIF('30_NGAN_HANG'!$B:$B,A13)) | Q13: =IF(A13="","",COUNTIFS('30_NGAN_HANG'!$B:$B,A13,'30_NGAN_HANG'!$Y:$Y,"Approved"))
P14: =IF(A14="","",COUNTIF('30_NGAN_HANG'!$B:$B,A14)) | Q14: =IF(A14="","",COUNTIFS('30_NGAN_HANG'!$B:$B,A14,'30_NGAN_HANG'!$Y:$Y,"Approved"))
P15: =IF(A15="","",COUNTIF('30_NGAN_HANG'!$B:$B,A15)) | Q15: =IF(A15="","",COUNTIFS('30_NGAN_HANG'!$B:$B,A15,'30_NGAN_HANG'!$Y:$Y,"Approved"))
... P300: =IF(A300="","",COUNTIF('30_NGAN_HANG'!$B:$B,A300)) | Q300: =IF(A300="","",COUNTIFS('30_NGAN_HANG'!$B:$B,A300,'30_NGAN_HANG'!$Y:$Y,"Approved"))

Sheet IN_09_指示の聴解
A1: 聴解 › 指示の聴解 | 1 dòng = 1 yêu cầu sinh câu. Cam = bắt buộc, vàng = gợi ý cho AI.
A2: Mã yêu cầu | B2: Mã đề (kế hoạch) | C2: Quyển | D2: Bài | E2: Số câu cần sinh | F2: Người chỉ thị → người nhận | G2: Nhiệm vụ | H2: Câu hỏi | I2: Số bước trong chỉ thị | J2: Thông tin bẫy | K2: Kiểu đáp án | L2: Ghi chú cho AI | M2: Công cụ sinh | N2: Người nhập | O2: Trạng thái | P2: Số câu đã sinh | Q2: Số câu Approved
A3: IN_09-0001 | C3: 入門 | D3: 1 | E3: 3 | F3: sếp → nhân viên mới | G3: Chuẩn bị phòng họp | H3: Đầu tiên phải làm gì? | I3: 3 | J3: Bước photo tài liệu bị huỷ | K3: Hình 4 ô | L3: VÍ DỤ — xoá dòng này khi dùng thật | M3: ChatGPT | O3: Nháp | P3: =IF(A3="","",COUNTIF('30_NGAN_HANG'!$B:$B,A3)) | Q3: =IF(A3="","",COUNTIFS('30_NGAN_HANG'!$B:$B,A3,'30_NGAN_HANG'!$Y:$Y,"Approved"))
P4: =IF(A4="","",COUNTIF('30_NGAN_HANG'!$B:$B,A4)) | Q4: =IF(A4="","",COUNTIFS('30_NGAN_HANG'!$B:$B,A4,'30_NGAN_HANG'!$Y:$Y,"Approved"))
P5: =IF(A5="","",COUNTIF('30_NGAN_HANG'!$B:$B,A5)) | Q5: =IF(A5="","",COUNTIFS('30_NGAN_HANG'!$B:$B,A5,'30_NGAN_HANG'!$Y:$Y,"Approved"))
P6: =IF(A6="","",COUNTIF('30_NGAN_HANG'!$B:$B,A6)) | Q6: =IF(A6="","",COUNTIFS('30_NGAN_HANG'!$B:$B,A6,'30_NGAN_HANG'!$Y:$Y,"Approved"))
P7: =IF(A7="","",COUNTIF('30_NGAN_HANG'!$B:$B,A7)) | Q7: =IF(A7="","",COUNTIFS('30_NGAN_HANG'!$B:$B,A7,'30_NGAN_HANG'!$Y:$Y,"Approved"))
P8: =IF(A8="","",COUNTIF('30_NGAN_HANG'!$B:$B,A8)) | Q8: =IF(A8="","",COUNTIFS('30_NGAN_HANG'!$B:$B,A8,'30_NGAN_HANG'!$Y:$Y,"Approved"))
P9: =IF(A9="","",COUNTIF('30_NGAN_HANG'!$B:$B,A9)) | Q9: =IF(A9="","",COUNTIFS('30_NGAN_HANG'!$B:$B,A9,'30_NGAN_HANG'!$Y:$Y,"Approved"))
P10: =IF(A10="","",COUNTIF('30_NGAN_HANG'!$B:$B,A10)) | Q10: =IF(A10="","",COUNTIFS('30_NGAN_HANG'!$B:$B,A10,'30_NGAN_HANG'!$Y:$Y,"Approved"))
P11: =IF(A11="","",COUNTIF('30_NGAN_HANG'!$B:$B,A11)) | Q11: =IF(A11="","",COUNTIFS('30_NGAN_HANG'!$B:$B,A11,'30_NGAN_HANG'!$Y:$Y,"Approved"))
P12: =IF(A12="","",COUNTIF('30_NGAN_HANG'!$B:$B,A12)) | Q12: =IF(A12="","",COUNTIFS('30_NGAN_HANG'!$B:$B,A12,'30_NGAN_HANG'!$Y:$Y,"Approved"))
P13: =IF(A13="","",COUNTIF('30_NGAN_HANG'!$B:$B,A13)) | Q13: =IF(A13="","",COUNTIFS('30_NGAN_HANG'!$B:$B,A13,'30_NGAN_HANG'!$Y:$Y,"Approved"))
P14: =IF(A14="","",COUNTIF('30_NGAN_HANG'!$B:$B,A14)) | Q14: =IF(A14="","",COUNTIFS('30_NGAN_HANG'!$B:$B,A14,'30_NGAN_HANG'!$Y:$Y,"Approved"))
P15: =IF(A15="","",COUNTIF('30_NGAN_HANG'!$B:$B,A15)) | Q15: =IF(A15="","",COUNTIFS('30_NGAN_HANG'!$B:$B,A15,'30_NGAN_HANG'!$Y:$Y,"Approved"))
... P300: =IF(A300="","",COUNTIF('30_NGAN_HANG'!$B:$B,A300)) | Q300: =IF(A300="","",COUNTIFS('30_NGAN_HANG'!$B:$B,A300,'30_NGAN_HANG'!$Y:$Y,"Approved"))

Sheet IN_10_掲示の読解
A1: 読解 › 掲示の読解 | 1 dòng = 1 yêu cầu sinh câu. Cam = bắt buộc, vàng = gợi ý cho AI.
A2: Mã yêu cầu | B2: Mã đề (kế hoạch) | C2: Quyển | D2: Bài | E2: Số câu cần sinh | F2: Loại văn bản | G2: Bối cảnh | H2: Câu hỏi | I2: Thông tin chính cần có | J2: Thông tin nhiễu | K2: Cần hình? | L2: Ghi chú cho AI | M2: Công cụ sinh | N2: Người nhập | O2: Trạng thái | P2: Số câu đã sinh | Q2: Số câu Approved
A3: IN_10-0001 | C3: 入門 | D3: 1 | E3: 3 | F3: Thông báo đổ rác | G3: Khu chung cư | H3: Rác cháy được bỏ ngày nào? | I3: Thứ 2;Thứ 5;trước 8 giờ | J3: Ngày rác nhựa | K3: Y | L3: VÍ DỤ — xoá dòng này khi dùng thật | M3: ChatGPT | O3: Nháp | P3: =IF(A3="","",COUNTIF('30_NGAN_HANG'!$B:$B,A3)) | Q3: =IF(A3="","",COUNTIFS('30_NGAN_HANG'!$B:$B,A3,'30_NGAN_HANG'!$Y:$Y,"Approved"))
P4: =IF(A4="","",COUNTIF('30_NGAN_HANG'!$B:$B,A4)) | Q4: =IF(A4="","",COUNTIFS('30_NGAN_HANG'!$B:$B,A4,'30_NGAN_HANG'!$Y:$Y,"Approved"))
P5: =IF(A5="","",COUNTIF('30_NGAN_HANG'!$B:$B,A5)) | Q5: =IF(A5="","",COUNTIFS('30_NGAN_HANG'!$B:$B,A5,'30_NGAN_HANG'!$Y:$Y,"Approved"))
P6: =IF(A6="","",COUNTIF('30_NGAN_HANG'!$B:$B,A6)) | Q6: =IF(A6="","",COUNTIFS('30_NGAN_HANG'!$B:$B,A6,'30_NGAN_HANG'!$Y:$Y,"Approved"))
P7: =IF(A7="","",COUNTIF('30_NGAN_HANG'!$B:$B,A7)) | Q7: =IF(A7="","",COUNTIFS('30_NGAN_HANG'!$B:$B,A7,'30_NGAN_HANG'!$Y:$Y,"Approved"))
P8: =IF(A8="","",COUNTIF('30_NGAN_HANG'!$B:$B,A8)) | Q8: =IF(A8="","",COUNTIFS('30_NGAN_HANG'!$B:$B,A8,'30_NGAN_HANG'!$Y:$Y,"Approved"))
P9: =IF(A9="","",COUNTIF('30_NGAN_HANG'!$B:$B,A9)) | Q9: =IF(A9="","",COUNTIFS('30_NGAN_HANG'!$B:$B,A9,'30_NGAN_HANG'!$Y:$Y,"Approved"))
P10: =IF(A10="","",COUNTIF('30_NGAN_HANG'!$B:$B,A10)) | Q10: =IF(A10="","",COUNTIFS('30_NGAN_HANG'!$B:$B,A10,'30_NGAN_HANG'!$Y:$Y,"Approved"))
P11: =IF(A11="","",COUNTIF('30_NGAN_HANG'!$B:$B,A11)) | Q11: =IF(A11="","",COUNTIFS('30_NGAN_HANG'!$B:$B,A11,'30_NGAN_HANG'!$Y:$Y,"Approved"))
P12: =IF(A12="","",COUNTIF('30_NGAN_HANG'!$B:$B,A12)) | Q12: =IF(A12="","",COUNTIFS('30_NGAN_HANG'!$B:$B,A12,'30_NGAN_HANG'!$Y:$Y,"Approved"))
P13: =IF(A13="","",COUNTIF('30_NGAN_HANG'!$B:$B,A13)) | Q13: =IF(A13="","",COUNTIFS('30_NGAN_HANG'!$B:$B,A13,'30_NGAN_HANG'!$Y:$Y,"Approved"))
P14: =IF(A14="","",COUNTIF('30_NGAN_HANG'!$B:$B,A14)) | Q14: =IF(A14="","",COUNTIFS('30_NGAN_HANG'!$B:$B,A14,'30_NGAN_HANG'!$Y:$Y,"Approved"))
P15: =IF(A15="","",COUNTIF('30_NGAN_HANG'!$B:$B,A15)) | Q15: =IF(A15="","",COUNTIFS('30_NGAN_HANG'!$B:$B,A15,'30_NGAN_HANG'!$Y:$Y,"Approved"))
... P300: =IF(A300="","",COUNTIF('30_NGAN_HANG'!$B:$B,A300)) | Q300: =IF(A300="","",COUNTIFS('30_NGAN_HANG'!$B:$B,A300,'30_NGAN_HANG'!$Y:$Y,"Approved"))

Sheet IN_11_文章の読解
A1: 読解 › 文章の読解 | 1 dòng = 1 yêu cầu sinh câu. Cam = bắt buộc, vàng = gợi ý cho AI.
A2: Mã yêu cầu | B2: Mã đề (kế hoạch) | C2: Quyển | D2: Bài | E2: Số câu cần sinh | F2: Thể loại | G2: Chủ đề | H2: Số câu hỏi con | I2: Độ dài (字) | J2: Người viết → người đọc | K2: Ý chính cần hỏi | L2: Ghi chú cho AI | M2: Công cụ sinh | N2: Người nhập | O2: Trạng thái | P2: Số câu đã sinh | Q2: Số câu Approved
A3: IN_11-0001 | C3: 入門 | D3: 1 | E3: 3 | F3: Email | G3: Mời tiệc chia tay đồng nghiệp | H3: 2 | I3: 250 | J3: đồng nghiệp → cả phòng | K3: Thời gian;Cần mang gì | L3: VÍ DỤ — xoá dòng này khi dùng thật | M3: ChatGPT | O3: Nháp | P3: =IF(A3="","",COUNTIF('30_NGAN_HANG'!$B:$B,A3)) | Q3: =IF(A3="","",COUNTIFS('30_NGAN_HANG'!$B:$B,A3,'30_NGAN_HANG'!$Y:$Y,"Approved"))
P4: =IF(A4="","",COUNTIF('30_NGAN_HANG'!$B:$B,A4)) | Q4: =IF(A4="","",COUNTIFS('30_NGAN_HANG'!$B:$B,A4,'30_NGAN_HANG'!$Y:$Y,"Approved"))
P5: =IF(A5="","",COUNTIF('30_NGAN_HANG'!$B:$B,A5)) | Q5: =IF(A5="","",COUNTIFS('30_NGAN_HANG'!$B:$B,A5,'30_NGAN_HANG'!$Y:$Y,"Approved"))
P6: =IF(A6="","",COUNTIF('30_NGAN_HANG'!$B:$B,A6)) | Q6: =IF(A6="","",COUNTIFS('30_NGAN_HANG'!$B:$B,A6,'30_NGAN_HANG'!$Y:$Y,"Approved"))
P7: =IF(A7="","",COUNTIF('30_NGAN_HANG'!$B:$B,A7)) | Q7: =IF(A7="","",COUNTIFS('30_NGAN_HANG'!$B:$B,A7,'30_NGAN_HANG'!$Y:$Y,"Approved"))
P8: =IF(A8="","",COUNTIF('30_NGAN_HANG'!$B:$B,A8)) | Q8: =IF(A8="","",COUNTIFS('30_NGAN_HANG'!$B:$B,A8,'30_NGAN_HANG'!$Y:$Y,"Approved"))
P9: =IF(A9="","",COUNTIF('30_NGAN_HANG'!$B:$B,A9)) | Q9: =IF(A9="","",COUNTIFS('30_NGAN_HANG'!$B:$B,A9,'30_NGAN_HANG'!$Y:$Y,"Approved"))
P10: =IF(A10="","",COUNTIF('30_NGAN_HANG'!$B:$B,A10)) | Q10: =IF(A10="","",COUNTIFS('30_NGAN_HANG'!$B:$B,A10,'30_NGAN_HANG'!$Y:$Y,"Approved"))
P11: =IF(A11="","",COUNTIF('30_NGAN_HANG'!$B:$B,A11)) | Q11: =IF(A11="","",COUNTIFS('30_NGAN_HANG'!$B:$B,A11,'30_NGAN_HANG'!$Y:$Y,"Approved"))
P12: =IF(A12="","",COUNTIF('30_NGAN_HANG'!$B:$B,A12)) | Q12: =IF(A12="","",COUNTIFS('30_NGAN_HANG'!$B:$B,A12,'30_NGAN_HANG'!$Y:$Y,"Approved"))
P13: =IF(A13="","",COUNTIF('30_NGAN_HANG'!$B:$B,A13)) | Q13: =IF(A13="","",COUNTIFS('30_NGAN_HANG'!$B:$B,A13,'30_NGAN_HANG'!$Y:$Y,"Approved"))
P14: =IF(A14="","",COUNTIF('30_NGAN_HANG'!$B:$B,A14)) | Q14: =IF(A14="","",COUNTIFS('30_NGAN_HANG'!$B:$B,A14,'30_NGAN_HANG'!$Y:$Y,"Approved"))
P15: =IF(A15="","",COUNTIF('30_NGAN_HANG'!$B:$B,A15)) | Q15: =IF(A15="","",COUNTIFS('30_NGAN_HANG'!$B:$B,A15,'30_NGAN_HANG'!$Y:$Y,"Approved"))
... P300: =IF(A300="","",COUNTIF('30_NGAN_HANG'!$B:$B,A300)) | Q300: =IF(A300="","",COUNTIFS('30_NGAN_HANG'!$B:$B,A300,'30_NGAN_HANG'!$Y:$Y,"Approved"))

Sheet 20_PROMPT
A1: Dạng bài | B1: Prompt chung (system) | C1: Prompt riêng (user) — {biến} = tên cột IN_xx | D1: Định dạng JSON đầu ra | E1: Phiên bản | F1: Ghi chú cải tiến
A2: 語の意味 | B2: あなたはJFT-Basicの作問者です。出題範囲は『いろどり』{Quyển} 第{Bài}課まで。範囲外の語彙・漢字・文法は使わない。4択・正答1つ。正答位置はばらつかせる。解説はベトナム語で、正答の理由と各誤答の理由を書く。出力はJSON配列のみ。 | C2: 「{Từ đích}」（{Nghĩa tiếng Việt}）の意味を問う問題を{Số câu cần sinh}問。形式: {Kiểu đáp án}。文脈: {Ngữ cảnh câu hỏi}。誤答候補: {Từ nhiễu gợi ý} | D2: [{"Stem":"","Script":"","Option1":"","Option2":"","Option3":"","Option4":"","Answer":1,"Explanation_VI":"","ImagePrompt":""}] | E2: v1
A3: 語の使い方 | B3: あなたはJFT-Basicの作問者です。出題範囲は『いろどり』{Quyển} 第{Bài}課まで。範囲外の語彙・漢字・文法は使わない。4択・正答1つ。正答位置はばらつかせる。解説はベトナム語で、正答の理由と各誤答の理由を書く。出力はJSON配列のみ。 | C3: 「{Từ đích}」を正しく使えるか問う問題。文: {Câu ngữ cảnh (có ___)}。正しいコロケーション: {Collocation đúng}。狙う誤用: {Lỗi dùng từ muốn bẫy} | D3: [{"Stem":"","Script":"","Option1":"","Option2":"","Option3":"","Option4":"","Answer":1,"Explanation_VI":"","ImagePrompt":""}] | E3: v1
A4: 漢字の読み | B4: あなたはJFT-Basicの作問者です。出題範囲は『いろどり』{Quyển} 第{Bài}課まで。範囲外の語彙・漢字・文法は使わない。4択・正答1つ。正答位置はばらつかせる。解説はベトナム語で、正答の理由と各誤答の理由を書く。出力はJSON配列のみ。 | C4: 下線部「{Từ chứa kanji (gạch chân)}」の読み（正答: {Cách đọc đúng}）を問う。文: {Câu ngữ cảnh}。誤答の作り方: {Kiểu nhiễu} | D4: [{"Stem":"","Script":"","Option1":"","Option2":"","Option3":"","Option4":"","Answer":1,"Explanation_VI":"","ImagePrompt":""}] | E4: v1
A5: 漢字の表記 | B5: あなたはJFT-Basicの作問者です。出題範囲は『いろどり』{Quyển} 第{Bài}課まで。範囲外の語彙・漢字・文法は使わない。4択・正答1つ。正答位置はばらつかせる。解説はベトナム語で、正答の理由と各誤答の理由を書く。出力はJSON配列のみ。 | C5: 下線部「{Từ viết hiragana (gạch chân)}」の漢字（正答: {Kanji đúng}）を問う。文: {Câu ngữ cảnh}。誤答候補: {Kanji nhiễu} | D5: [{"Stem":"","Script":"","Option1":"","Option2":"","Option3":"","Option4":"","Answer":1,"Explanation_VI":"","ImagePrompt":""}] | E5: v1
A6: 表現 | B6: あなたはJFT-Basicの作問者です。出題範囲は『いろどり』{Quyển} 第{Bài}課まで。範囲外の語彙・漢字・文法は使わない。4択・正答1つ。正答位置はばらつかせる。解説はベトナム語で、正答の理由と各誤答の理由を書く。出力はJSON配列のみ。 | C6: 場面: {Mô tả tình huống (VN hoặc JP)}。{Người nói → người nghe}、機能: {Chức năng giao tiếp}、丁寧さ: {Mức lịch sự}。適切な発話を選ぶ問題。正答例: {Câu đúng mong muốn}。誤答候補: {Câu nhiễu gợi ý} | D6: [{"Stem":"","Script":"","Option1":"","Option2":"","Option3":"","Option4":"","Answer":1,"Explanation_VI":"","ImagePrompt":""}] | E6: v1
A7: 文法 | B7: あなたはJFT-Basicの作問者です。出題範囲は『いろどり』{Quyển} 第{Bài}課まで。範囲外の語彙・漢字・文法は使わない。4択・正答1つ。正答位置はばらつかせる。解説はベトナム語で、正答の理由と各誤答の理由を書く。出力はJSON配列のみ。 | C7: 文法項目「{Mẫu ngữ pháp đích}」。形式: {Dạng câu}。場面: {Ngữ cảnh}。空欄位置: {Vị trí ô trống}。誤答に使う項目: {Mẫu dễ nhầm làm nhiễu} | D7: [{"Stem":"","Script":"","Option1":"","Option2":"","Option3":"","Option4":"","Answer":1,"Explanation_VI":"","ImagePrompt":""}] | E7: v1
